Workbook
Name Initials: 'By Player'!$A$2:$A$5
Name Players: 'By Player'!$A$2:$A$5

Sheet Revolutions
A1: RevolutionID | B1: Date | C1: StartTime | D1: EndTime | E1: Duration | F1: LX | G1: ML | H1: MN | I1: VM | J1: Notes
A2: ="R"&TEXT(B2,"yyyymmdd")&"-"&COUNTIFS($B:$B,B2,$C:$C,"<="&C2) -> R20251201-1 | B2: 45992 | C2: 0.8125 | D2: 0.9375 | E2: =MOD(D2 - C2, 1) -> 0.125 | F2: {=COUNTIFS( Matches!$A$2:$A$200,$A2, Matches!$I$2:$I$200,"*"&F$1&"*" ) &" ("& SUMPRODUCT( (Matches!$A$2:$A$200=$A2) * ((Matches!$C$2:$C$200=F$1)+(Matches!$D$2:$D$200=F$1)) * Matches!$G$2:$G$200 ) + SUMPRODUCT( (Matches!$A$2:$A$200=$A2) * ((Matches!$E$2:$E$200=F$1)+(Matches!$F$2:$F$200=F$1)) * Matches!$H$2:$H$200 ) &")"} -> 2 (26) | G2: {=COUNTIFS( Matches!$A$2:$A$200,$A2, Matches!$I$2:$I$200,"*"&G$1&"*" ) &" ("& SUMPRODUCT( (Matches!$A$2:$A$200=$A2) * ((Matches!$C$2:$C$200=G$1)+(Matches!$D$2:$D$200=G$1)) * Matches!$G$2:$G$200 ) + SUMPRODUCT( (Matches!$A$2:$A$200=$A2) * ((Matches!$E$2:$E$200=G$1)+(Matches!$F$2:$F$200=G$1)) * Matches!$H$2:$H$200 ) &")"} -> 2 (25) | H2: {=COUNTIFS( Matches!$A$2:$A$200,$A2, Matches!$I$2:$I$200,"*"&H$1&"*" ) &" ("& SUMPRODUCT( (Matches!$A$2:$A$200=$A2) * ((Matches!$C$2:$C$200=H$1)+(Matches!$D$2:$D$200=H$1)) * Matches!$G$2:$G$200 ) + SUMPRODUCT( (Matches!$A$2:$A$200=$A2) * ((Matches!$E$2:$E$200=H$1)+(Matches!$F$2:$F$200=H$1)) * Matches!$H$2:$H$200 ) &")"} -> 2 (23) | I2: {=COUNTIFS( Matches!$A$2:$A$200,$A2, Matches!$I$2:$I$200,"*"&I$1&"*" ) &" ("& SUMPRODUCT( (Matches!$A$2:$A$200=$A2) * ((Matches!$C$2:$C$200=I$1)+(Matches!$D$2:$D$200=I$1)) * Matches!$G$2:$G$200 ) + SUMPRODUCT( (Matches!$A$2:$A$200=$A2) * ((Matches!$E$2:$E$200=I$1)+(Matches!$F$2:$F$200=I$1)) * Matches!$H$2:$H$200 ) &")"} -> 0 (14)
A3: ="R"&TEXT(B3,"yyyymmdd")&"-"&COUNTIFS($B:$B,B3,$C:$C,"<="&C3) -> R20251215-1 | B3: 46006 | C3: 0.6875 | D3: 0.85416667 | E3: =MOD(D3 - C3, 1) -> 0.16666667 | F3: {=COUNTIFS( Matches!$A$2:$A$200,$A3, Matches!$I$2:$I$200,"*"&F$1&"*" ) &" ("& SUMPRODUCT( (Matches!$A$2:$A$200=$A3) * ((Matches!$C$2:$C$200=F$1)+(Matches!$D$2:$D$200=F$1)) * Matches!$G$2:$G$200 ) + SUMPRODUCT( (Matches!$A$2:$A$200=$A3) * ((Matches!$E$2:$E$200=F$1)+(Matches!$F$2:$F$200=F$1)) * Matches!$H$2:$H$200 ) &")"} -> 1 (22) | G3: {=COUNTIFS( Matches!$A$2:$A$200,$A3, Matches!$I$2:$I$200,"*"&G$1&"*" ) &" ("& SUMPRODUCT( (Matches!$A$2:$A$200=$A3) * ((Matches!$C$2:$C$200=G$1)+(Matches!$D$2:$D$200=G$1)) * Matches!$G$2:$G$200 ) + SUMPRODUCT( (Matches!$A$2:$A$200=$A3) * ((Matches!$E$2:$E$200=G$1)+(Matches!$F$2:$F$200=G$1)) * Matches!$H$2:$H$200 ) &")"} -> 3 (30) | H3: {=COUNTIFS( Matches!$A$2:$A$200,$A3, Matches!$I$2:$I$200,"*"&H$1&"*" ) &" ("& SUMPRODUCT( (Matches!$A$2:$A$200=$A3) * ((Matches!$C$2:$C$200=H$1)+(Matches!$D$2:$D$200=H$1)) * Matches!$G$2:$G$200 ) + SUMPRODUCT( (Matches!$A$2:$A$200=$A3) * ((Matches!$E$2:$E$200=H$1)+(Matches!$F$2:$F$200=H$1)) * Matches!$H$2:$H$200 ) &")"} -> 1 (22) | I3: {=COUNTIFS( Matches!$A$2:$A$200,$A3, Matches!$I$2:$I$200,"*"&I$1&"*" ) &" ("& SUMPRODUCT( (Matches!$A$2:$A$200=$A3) * ((Matches!$C$2:$C$200=I$1)+(Matches!$D$2:$D$200=I$1)) * Matches!$G$2:$G$200 ) + SUMPRODUCT( (Matches!$A$2:$A$200=$A3) * ((Matches!$E$2:$E$200=I$1)+(Matches!$F$2:$F$200=I$1)) * Matches!$H$2:$H$200 ) &")"} -> 1 (28)
A4: ="R"&TEXT(B4,"yyyymmdd")&"-"&COUNTIFS($B:$B,B4,$C:$C,"<="&C4) -> R20251229-1 | B4: 46020 | C4: 0.54166667 | D4: 0.66666667 | E4: =MOD(D4 - C4, 1) -> 0.125 | F4: {=COUNTIFS( Matches!$A$2:$A$200,$A4, Matches!$I$2:$I$200,"*"&F$1&"*" ) &" ("& SUMPRODUCT( (Matches!$A$2:$A$200=$A4) * ((Matches!$C$2:$C$200=F$1)+(Matches!$D$2:$D$200=F$1)) * Matches!$G$2:$G$200 ) + SUMPRODUCT( (Matches!$A$2:$A$200=$A4) * ((Matches!$E$2:$E$200=F$1)+(Matches!$F$2:$F$200=F$1)) * Matches!$H$2:$H$200 ) &")"} -> 0 (17) | G4: {=COUNTIFS( Matches!$A$2:$A$200,$A4, Matches!$I$2:$I$200,"*"&G$1&"*" ) &" ("& SUMPRODUCT( (Matches!$A$2:$A$200=$A4) * ((Matches!$C$2:$C$200=G$1)+(Matches!$D$2:$D$200=G$1)) * Matches!$G$2:$G$200 ) + SUMPRODUCT( (Matches!$A$2:$A$200=$A4) * ((Matches!$E$2:$E$200=G$1)+(Matches!$F$2:$F$200=G$1)) * Matches!$H$2:$H$200 ) &")"} -> 2 (22) | H4: {=COUNTIFS( Matches!$A$2:$A$200,$A4, Matches!$I$2:$I$200,"*"&H$1&"*" ) &" ("& SUMPRODUCT( (Matches!$A$2:$A$200=$A4) * ((Matches!$C$2:$C$200=H$1)+(Matches!$D$2:$D$200=H$1)) * Matches!$G$2:$G$200 ) + SUMPRODUCT( (Matches!$A$2:$A$200=$A4) * ((Matches!$E$2:$E$200=H$1)+(Matches!$F$2:$F$200=H$1)) * Matches!$H$2:$H$200 ) &")"} -> 2 (29) | I4: {=COUNTIFS( Matches!$A$2:$A$200,$A4, Matches!$I$2:$I$200,"*"&I$1&"*" ) &" ("& SUMPRODUCT( (Matches!$A$2:$A$200=$A4) * ((Matches!$C$2:$C$200=I$1)+(Matches!$D$2:$D$200=I$1)) * Matches!$G$2:$G$200 ) + SUMPRODUCT( (Matches!$A$2:$A$200=$A4) * ((Matches!$E$2:$E$200=I$1)+(Matches!$F$2:$F$200=I$1)) * Matches!$H$2:$H$200 ) &")"} -> 2 (26)
A5: ="R"&TEXT(B5,"yyyymmdd")&"-"&COUNTIFS($B:$B,B5,$C:$C,"<="&C5) -> R20251229-2 | B5: 46020 | C5: 0.66666667 | D5: 0 | E5: =MOD(D5 - C5, 1) -> 0.33333333 | F5: {=COUNTIFS( Matches!$A$2:$A$200,$A5, Matches!$I$2:$I$200,"*"&F$1&"*" ) &" ("& SUMPRODUCT( (Matches!$A$2:$A$200=$A5) * ((Matches!$C$2:$C$200=F$1)+(Matches!$D$2:$D$200=F$1)) * Matches!$G$2:$G$200 ) + SUMPRODUCT( (Matches!$A$2:$A$200=$A5) * ((Matches!$E$2:$E$200=F$1)+(Matches!$F$2:$F$200=F$1)) * Matches!$H$2:$H$200 ) &")"} -> 2 (29) | G5: {=COUNTIFS( Matches!$A$2:$A$200,$A5, Matches!$I$2:$I$200,"*"&G$1&"*" ) &" ("& SUMPRODUCT( (Matches!$A$2:$A$200=$A5) * ((Matches!$C$2:$C$200=G$1)+(Matches!$D$2:$D$200=G$1)) * Matches!$G$2:$G$200 ) + SUMPRODUCT( (Matches!$A$2:$A$200=$A5) * ((Matches!$E$2:$E$200=G$1)+(Matches!$F$2:$F$200=G$1)) * Matches!$H$2:$H$200 ) &")"} -> 2 (25) | H5: {=COUNTIFS( Matches!$A$2:$A$200,$A5, Matches!$I$2:$I$200,"*"&H$1&"*" ) &" ("& SUMPRODUCT( (Matches!$A$2:$A$200=$A5) * ((Matches!$C$2:$C$200=H$1)+(Matches!$D$2:$D$200=H$1)) * Matches!$G$2:$G$200 ) + SUMPRODUCT( (Matches!$A$2:$A$200=$A5) * ((Matches!$E$2:$E$200=H$1)+(Matches!$F$2:$F$200=H$1)) * Matches!$H$2:$H$200 ) &")"} -> 2 (26) | I5: {=COUNTIFS( Matches!$A$2:$A$200,$A5, Matches!$I$2:$I$200,"*"&I$1&"*" ) &" ("& SUMPRODUCT( (Matches!$A$2:$A$200=$A5) * ((Matches!$C$2:$C$200=I$1)+(Matches!$D$2:$D$200=I$1)) * Matches!$G$2:$G$200 ) + SUMPRODUCT( (Matches!$A$2:$A$200=$A5) * ((Matches!$E$2:$E$200=I$1)+(Matches!$F$2:$F$200=I$1)) * Matches!$H$2:$H$200 ) &")"} -> 0 (20)
A6: ="R"&TEXT(B6,"yyyymmdd")&"-"&COUNTIFS($B:$B,B6,$C:$C,"<="&C6) -> R20260105-1 | B6: 46027 | C6: 0.64583333 | D6: 0.75 | E6: =MOD(D6 - C6, 1) -> 0.10416667 | F6: {=COUNTIFS( Matches!$A$2:$A$200,$A6, Matches!$I$2:$I$200,"*"&F$1&"*" ) &" ("& SUMPRODUCT( (Matches!$A$2:$A$200=$A6) * ((Matches!$C$2:$C$200=F$1)+(Matches!$D$2:$D$200=F$1)) * Matches!$G$2:$G$200 ) + SUMPRODUCT( (Matches!$A$2:$A$200=$A6) * ((Matches!$E$2:$E$200=F$1)+(Matches!$F$2:$F$200=F$1)) * Matches!$H$2:$H$200 ) &")"} -> 2 (22) | G6: {=COUNTIFS( Matches!$A$2:$A$200,$A6, Matches!$I$2:$I$200,"*"&G$1&"*" ) &" ("& SUMPRODUCT( (Matches!$A$2:$A$200=$A6) * ((Matches!$C$2:$C$200=G$1)+(Matches!$D$2:$D$200=G$1)) * Matches!$G$2:$G$200 ) + SUMPRODUCT( (Matches!$A$2:$A$200=$A6) * ((Matches!$E$2:$E$200=G$1)+(Matches!$F$2:$F$200=G$1)) * Matches!$H$2:$H$200 ) &")"} -> 2 (26) | H6: {=COUNTIFS( Matches!$A$2:$A$200,$A6, Matches!$I$2:$I$200,"*"&H$1&"*" ) &" ("& SUMPRODUCT( (Matches!$A$2:$A$200=$A6) * ((Matches!$C$2:$C$200=H$1)+(Matches!$D$2:$D$200=H$1)) * Matches!$G$2:$G$200 ) + SUMPRODUCT( (Matches!$A$2:$A$200=$A6) * ((Matches!$E$2:$E$200=H$1)+(Matches!$F$2:$F$200=H$1)) * Matches!$H$2:$H$200 ) &")"} -> 2 (25) | I6: {=COUNTIFS( Matches!$A$2:$A$200,$A6, Matches!$I$2:$I$200,"*"&I$1&"*" ) &" ("& SUMPRODUCT( (Matches!$A$2:$A$200=$A6) * ((Matches!$C$2:$C$200=I$1)+(Matches!$D$2:$D$200=I$1)) * Matches!$G$2:$G$200 ) + SUMPRODUCT( (Matches!$A$2:$A$200=$A6) * ((Matches!$E$2:$E$200=I$1)+(Matches!$F$2:$F$200=I$1)) * Matches!$H$2:$H$200 ) &")"} -> 0 (13)
A7: ="R"&TEXT(B7,"yyyymmdd")&"-"&COUNTIFS($B:$B,B7,$C:$C,"<="&C7) -> R20260105-2 | B7: 46027 | C7: 0.79166667 | D7: 0.875 | E7: =MOD(D7 - C7, 1) -> 0.083333333 | F7: {=COUNTIFS( Matches!$A$2:$A$200,$A7, Matches!$I$2:$I$200,"*"&F$1&"*" ) &" ("& SUMPRODUCT( (Matches!$A$2:$A$200=$A7) * ((Matches!$C$2:$C$200=F$1)+(Matches!$D$2:$D$200=F$1)) * Matches!$G$2:$G$200 ) + SUMPRODUCT( (Matches!$A$2:$A$200=$A7) * ((Matches!$E$2:$E$200=F$1)+(Matches!$F$2:$F$200=F$1)) * Matches!$H$2:$H$200 ) &")"} -> 2 (24) | G7: {=COUNTIFS( Matches!$A$2:$A$200,$A7, Matches!$I$2:$I$200,"*"&G$1&"*" ) &" ("& SUMPRODUCT( (Matches!$A$2:$A$200=$A7) * ((Matches!$C$2:$C$200=G$1)+(Matches!$D$2:$D$200=G$1)) * Matches!$G$2:$G$200 ) + SUMPRODUCT( (Matches!$A$2:$A$200=$A7) * ((Matches!$E$2:$E$200=G$1)+(Matches!$F$2:$F$200=G$1)) * Matches!$H$2:$H$200 ) &")"} -> 0 (12) | H7: {=COUNTIFS( Matches!$A$2:$A$200,$A7, Matches!$I$2:$I$200,"*"&H$1&"*" ) &" ("& SUMPRODUCT( (Matches!$A$2:$A$200=$A7) * ((Matches!$C$2:$C$200=H$1)+(Matches!$D$2:$D$200=H$1)) * Matches!$G$2:$G$200 ) + SUMPRODUCT( (Matches!$A$2:$A$200=$A7) * ((Matches!$E$2:$E$200=H$1)+(Matches!$F$2:$F$200=H$1)) * Matches!$H$2:$H$200 ) &")"} -> 2 (26) | I7: {=COUNTIFS( Matches!$A$2:$A$200,$A7, Matches!$I$2:$I$200,"*"&I$1&"*" ) &" ("& SUMPRODUCT( (Matches!$A$2:$A$200=$A7) * ((Matches!$C$2:$C$200=I$1)+(Matches!$D$2:$D$200=I$1)) * Matches!$G$2:$G$200 ) + SUMPRODUCT( (Matches!$A$2:$A$200=$A7) * ((Matches!$E$2:$E$200=I$1)+(Matches!$F$2:$F$200=I$1)) * Matches!$H$2:$H$200 ) &")"} -> 2 (22)
A8: ="R"&TEXT(B8,"yyyymmdd")&"-"&COUNTIFS($B:$B,B8,$C:$C,"<="&C8) -> R20260112-1 | B8: 46034 | C8: 0.61458333 | D8: 0.73958333 | E8: =MOD(D8 - C8, 1) -> 0.125 | F8: {=COUNTIFS( Matches!$A$2:$A$200,$A8, Matches!$I$2:$I$200,"*"&F$1&"*" ) &" ("& SUMPRODUCT( (Matches!$A$2:$A$200=$A8) * ((Matches!$C$2:$C$200=F$1)+(Matches!$D$2:$D$200=F$1)) * Matches!$G$2:$G$200 ) + SUMPRODUCT( (Matches!$A$2:$A$200=$A8) * ((Matches!$E$2:$E$200=F$1)+(Matches!$F$2:$F$200=F$1)) * Matches!$H$2:$H$200 ) &")"} -> 2 (27) | G8: {=COUNTIFS( Matches!$A$2:$A$200,$A8, Matches!$I$2:$I$200,"*"&G$1&"*" ) &" ("& SUMPRODUCT( (Matches!$A$2:$A$200=$A8) * ((Matches!$C$2:$C$200=G$1)+(Matches!$D$2:$D$200=G$1)) * Matches!$G$2:$G$200 ) + SUMPRODUCT( (Matches!$A$2:$A$200=$A8) * ((Matches!$E$2:$E$200=G$1)+(Matches!$F$2:$F$200=G$1)) * Matches!$H$2:$H$200 ) &")"} -> 2 (27) | H8: {=COUNTIFS( Matches!$A$2:$A$200,$A8, Matches!$I$2:$I$200,"*"&H$1&"*" ) &" ("& SUMPRODUCT( (Matches!$A$2:$A$200=$A8) * ((Matches!$C$2:$C$200=H$1)+(Matches!$D$2:$D$200=H$1)) * Matches!$G$2:$G$200 ) + SUMPRODUCT( (Matches!$A$2:$A$200=$A8) * ((Matches!$E$2:$E$200=H$1)+(Matches!$F$2:$F$200=H$1)) * Matches!$H$2:$H$200 ) &")"} -> 2 (26) | I8: {=COUNTIFS( Matches!$A$2:$A$200,$A8, Matches!$I$2:$I$200,"*"&I$1&"*" ) &" ("& SUMPRODUCT( (Matches!$A$2:$A$200=$A8) * ((Matches!$C$2:$C$200=I$1)+(Matches!$D$2:$D$200=I$1)) * Matches!$G$2:$G$200 ) + SUMPRODUCT( (Matches!$A$2:$A$200=$A8) * ((Matches!$E$2:$E$200=I$1)+(Matches!$F$2:$F$200=I$1)) * Matches!$H$2:$H$200 ) &")"} -> 0 (20)
A9: ="R"&TEXT(B9,"yyyymmdd")&"-"&COUNTIFS($B:$B,B9,$C:$C,"<="&C9) -> R20260112-2 | B9: 46034 | C9: 0.83333333 | D9: 0.91666667 | E9: =MOD(D9 - C9, 1) -> 0.083333333 | F9: {=COUNTIFS( Matches!$A$2:$A$200,$A9, Matches!$I$2:$I$200,"*"&F$1&"*" ) &" ("& SUMPRODUCT( (Matches!$A$2:$A$200=$A9) * ((Matches!$C$2:$C$200=F$1)+(Matches!$D$2:$D$200=F$1)) * Matches!$G$2:$G$200 ) + SUMPRODUCT( (Matches!$A$2:$A$200=$A9) * ((Matches!$E$2:$E$200=F$1)+(Matches!$F$2:$F$200=F$1)) * Matches!$H$2:$H$200 ) &")"} -> 2 (20) | G9: {=COUNTIFS( Matches!$A$2:$A$200,$A9, Matches!$I$2:$I$200,"*"&G$1&"*" ) &" ("& SUMPRODUCT( (Matches!$A$2:$A$200=$A9) * ((Matches!$C$2:$C$200=G$1)+(Matches!$D$2:$D$200=G$1)) * Matches!$G$2:$G$200 ) + SUMPRODUCT( (Matches!$A$2:$A$200=$A9) * ((Matches!$E$2:$E$200=G$1)+(Matches!$F$2:$F$200=G$1)) * Matches!$H$2:$H$200 ) &")"} -> 2 (22) | H9: {=COUNTIFS( Matches!$A$2:$A$200,$A9, Matches!$I$2:$I$200,"*"&H$1&"*" ) &" ("& SUMPRODUCT( (Matches!$A$2:$A$200=$A9) * ((Matches!$C$2:$C$200=H$1)+(Matches!$D$2:$D$200=H$1)) * Matches!$G$2:$G$200 ) + SUMPRODUCT( (Matches!$A$2:$A$200=$A9) * ((Matches!$E$2:$E$200=H$1)+(Matches!$F$2:$F$200=H$1)) * Matches!$H$2:$H$200 ) &")"} -> 2 (28) | I9: {=COUNTIFS( Matches!$A$2:$A$200,$A9, Matches!$I$2:$I$200,"*"&I$1&"*" ) &" ("& SUMPRODUCT( (Matches!$A$2:$A$200=$A9) * ((Matches!$C$2:$C$200=I$1)+(Matches!$D$2:$D$200=I$1)) * Matches!$G$2:$G$200 ) + SUMPRODUCT( (Matches!$A$2:$A$200=$A9) * ((Matches!$E$2:$E$200=I$1)+(Matches!$F$2:$F$200=I$1)) * Matches!$H$2:$H$200 ) &")"} -> 0 (10)
A10: ="R"&TEXT(B10,"yyyymmdd")&"-"&COUNTIFS($B:$B,B10,$C:$C,"<="&C10) -> R20260119-1 | B10: 46041 | C10: 0.58333333 | D10: 0.67708333 | E10: =MOD(D10 - C10, 1) -> 0.09375 | F10: {=COUNTIFS( Matches!$A$2:$A$200,$A10, Matches!$I$2:$I$200,"*"&F$1&"*" ) &" ("& SUMPRODUCT( (Matches!$A$2:$A$200=$A10) * ((Matches!$C$2:$C$200=F$1)+(Matches!$D$2:$D$200=F$1)) * Matches!$G$2:$G$200 ) + SUMPRODUCT( (Matches!$A$2:$A$200=$A10) * ((Matches!$E$2:$E$200=F$1)+(Matches!$F$2:$F$200=F$1)) * Matches!$H$2:$H$200 ) &")"} -> 2 (29) | G10: {=COUNTIFS( Matches!$A$2:$A$200,$A10, Matches!$I$2:$I$200,"*"&G$1&"*" ) &" ("& SUMPRODUCT( (Matches!$A$2:$A$200=$A10) * ((Matches!$C$2:$C$200=G$1)+(Matches!$D$2:$D$200=G$1)) * Matches!$G$2:$G$200 ) + SUMPRODUCT( (Matches!$A$2:$A$200=$A10) * ((Matches!$E$2:$E$200=G$1)+(Matches!$F$2:$F$200=G$1)) * Matches!$H$2:$H$200 ) &")"} -> 2 (22) | H10: {=COUNTIFS( Matches!$A$2:$A$200,$A10, Matches!$I$2:$I$200,"*"&H$1&"*" ) &" ("& SUMPRODUCT( (Matches!$A$2:$A$200=$A10) * ((Matches!$C$2:$C$200=H$1)+(Matches!$D$2:$D$200=H$1)) * Matches!$G$2:$G$200 ) + SUMPRODUCT( (Matches!$A$2:$A$200=$A10) * ((Matches!$E$2:$E$200=H$1)+(Matches!$F$2:$F$200=H$1)) * Matches!$H$2:$H$200 ) &")"} -> 2 (25) | I10: {=COUNTIFS( Matches!$A$2:$A$200,$A10, Matches!$I$2:$I$200,"*"&I$1&"*" ) &" ("& SUMPRODUCT( (Matches!$A$2:$A$200=$A10) * ((Matches!$C$2:$C$200=I$1)+(Matches!$D$2:$D$200=I$1)) * Matches!$G$2:$G$200 ) + SUMPRODUCT( (Matches!$A$2:$A$200=$A10) * ((Matches!$E$2:$E$200=I$1)+(Matches!$F$2:$F$200=I$1)) * Matches!$H$2:$H$200 ) &")"} -> 0 (16)
A11: ="R"&TEXT(B11,"yyyymmdd")&"-"&COUNTIFS($B:$B,B11,$C:$C,"<="&C11) -> R20260119-2 | B11: 46041 | C11: 0.68055556 | D11: 0.77777778 | E11: =MOD(D11 - C11, 1) -> 0.097222222 | F11: {=COUNTIFS( Matches!$A$2:$A$200,$A11, Matches!$I$2:$I$200,"*"&F$1&"*" ) &" ("& SUMPRODUCT( (Matches!$A$2:$A$200=$A11) * ((Matches!$C$2:$C$200=F$1)+(Matches!$D$2:$D$200=F$1)) * Matches!$G$2:$G$200 ) + SUMPRODUCT( (Matches!$A$2:$A$200=$A11) * ((Matches!$E$2:$E$200=F$1)+(Matches!$F$2:$F$200=F$1)) * Matches!$H$2:$H$200 ) &")"} -> 2 (28) | G11: {=COUNTIFS( Matches!$A$2:$A$200,$A11, Matches!$I$2:$I$200,"*"&G$1&"*" ) &" ("& SUMPRODUCT( (Matches!$A$2:$A$200=$A11) * ((Matches!$C$2:$C$200=G$1)+(Matches!$D$2:$D$200=G$1)) * Matches!$G$2:$G$200 ) + SUMPRODUCT( (Matches!$A$2:$A$200=$A11) * ((Matches!$E$2:$E$200=G$1)+(Matches!$F$2:$F$200=G$1)) * Matches!$H$2:$H$200 ) &")"} -> 2 (25) | H11: {=COUNTIFS( Matches!$A$2:$A$200,$A11, Matches!$I$2:$I$200,"*"&H$1&"*" ) &" ("& SUMPRODUCT( (Matches!$A$2:$A$200=$A11) * ((Matches!$C$2:$C$200=H$1)+(Matches!$D$2:$D$200=H$1)) * Matches!$G$2:$G$200 ) + SUMPRODUCT( (Matches!$A$2:$A$200=$A11) * ((Matches!$E$2:$E$200=H$1)+(Matches!$F$2:$F$200=H$1)) * Matches!$H$2:$H$200 ) &")"} -> 2 (29) | I11: {=COUNTIFS( Matches!$A$2:$A$200,$A11, Matches!$I$2:$I$200,"*"&I$1&"*" ) &" ("& SUMPRODUCT( (Matches!$A$2:$A$200=$A11) * ((Matches!$C$2:$C$200=I$1)+(Matches!$D$2:$D$200=I$1)) * Matches!$G$2:$G$200 ) + SUMPRODUCT( (Matches!$A$2:$A$200=$A11) * ((Matches!$E$2:$E$200=I$1)+(Matches!$F$2:$F$200=I$1)) * Matches!$H$2:$H$200 ) &")"} -> 0 (22)
A12: ="R"&TEXT(B12,"yyyymmdd")&"-"&COUNTIFS($B:$B,B12,$C:$C,"<="&C12) -> R20260127-1 | B12: 46049 | C12: 0.53125 | D12: 0.61458333 | E12: =MOD(D12 - C12, 1) -> 0.083333333 | F12: {=COUNTIFS( Matches!$A$2:$A$200,$A12, Matches!$I$2:$I$200,"*"&F$1&"*" ) &" ("& SUMPRODUCT( (Matches!$A$2:$A$200=$A12) * ((Matches!$C$2:$C$200=F$1)+(Matches!$D$2:$D$200=F$1)) * Matches!$G$2:$G$200 ) + SUMPRODUCT( (Matches!$A$2:$A$200=$A12) * ((Matches!$E$2:$E$200=F$1)+(Matches!$F$2:$F$200=F$1)) * Matches!$H$2:$H$200 ) &")"} -> 1 (17) | G12: {=COUNTIFS( Matches!$A$2:$A$200,$A12, Matches!$I$2:$I$200,"*"&G$1&"*" ) &" ("& SUMPRODUCT( (Matches!$A$2:$A$200=$A12) * ((Matches!$C$2:$C$200=G$1)+(Matches!$D$2:$D$200=G$1)) * Matches!$G$2:$G$200 ) + SUMPRODUCT( (Matches!$A$2:$A$200=$A12) * ((Matches!$E$2:$E$200=G$1)+(Matches!$F$2:$F$200=G$1)) * Matches!$H$2:$H$200 ) &")"} -> 3 (30) | H12: {=COUNTIFS( Matches!$A$2:$A$200,$A12, Matches!$I$2:$I$200,"*"&H$1&"*" ) &" ("& SUMPRODUCT( (Matches!$A$2:$A$200=$A12) * ((Matches!$C$2:$C$200=H$1)+(Matches!$D$2:$D$200=H$1)) * Matches!$G$2:$G$200 ) + SUMPRODUCT( (Matches!$A$2:$A$200=$A12) * ((Matches!$E$2:$E$200=H$1)+(Matches!$F$2:$F$200=H$1)) * Matches!$H$2:$H$200 ) &")"} -> 1 (16) | I12: {=COUNTIFS( Matches!$A$2:$A$200,$A12, Matches!$I$2:$I$200,"*"&I$1&"*" ) &" ("& SUMPRODUCT( (Matches!$A$2:$A$200=$A12) * ((Matches!$C$2:$C$200=I$1)+(Matches!$D$2:$D$200=I$1)) * Matches!$G$2:$G$200 ) + SUMPRODUCT( (Matches!$A$2:$A$200=$A12) * ((Matches!$E$2:$E$200=I$1)+(Matches!$F$2:$F$200=I$1)) * Matches!$H$2:$H$200 ) &")"} -> 1 (15)
A13: ="R"&TEXT(B13,"yyyymmdd")&"-"&COUNTIFS($B:$B,B13,$C:$C,"<="&C13) -> R20260127-2 | B13: 46049 | C13: 0.65625 | D13: 0.76041667 | E13: =MOD(D13 - C13, 1) -> 0.10416667 | F13: {=COUNTIFS( Matches!$A$2:$A$200,$A13, Matches!$I$2:$I$200,"*"&F$1&"*" ) &" ("& SUMPRODUCT( (Matches!$A$2:$A$200=$A13) * ((Matches!$C$2:$C$200=F$1)+(Matches!$D$2:$D$200=F$1)) * Matches!$G$2:$G$200 ) + SUMPRODUCT( (Matches!$A$2:$A$200=$A13) * ((Matches!$E$2:$E$200=F$1)+(Matches!$F$2:$F$200=F$1)) * Matches!$H$2:$H$200 ) &")"} -> 2 (24) | G13: {=COUNTIFS( Matches!$A$2:$A$200,$A13, Matches!$I$2:$I$200,"*"&G$1&"*" ) &" ("& SUMPRODUCT( (Matches!$A$2:$A$200=$A13) * ((Matches!$C$2:$C$200=G$1)+(Matches!$D$2:$D$200=G$1)) * Matches!$G$2:$G$200 ) + SUMPRODUCT( (Matches!$A$2:$A$200=$A13) * ((Matches!$E$2:$E$200=G$1)+(Matches!$F$2:$F$200=G$1)) * Matches!$H$2:$H$200 ) &")"} -> 0 (19) | H13: {=COUNTIFS( Matches!$A$2:$A$200,$A13, Matches!$I$2:$I$200,"*"&H$1&"*" ) &" ("& SUMPRODUCT( (Matches!$A$2:$A$200=$A13) * ((Matches!$C$2:$C$200=H$1)+(Matches!$D$2:$D$200=H$1)) * Matches!$G$2:$G$200 ) + SUMPRODUCT( (Matches!$A$2:$A$200=$A13) * ((Matches!$E$2:$E$200=H$1)+(Matches!$F$2:$F$200=H$1)) * Matches!$H$2:$H$200 ) &")"} -> 2 (29) | I13: {=COUNTIFS( Matches!$A$2:$A$200,$A13, Matches!$I$2:$I$200,"*"&I$1&"*" ) &" ("& SUMPRODUCT( (Matches!$A$2:$A$200=$A13) * ((Matches!$C$2:$C$200=I$1)+(Matches!$D$2:$D$200=I$1)) * Matches!$G$2:$G$200 ) + SUMPRODUCT( (Matches!$A$2:$A$200=$A13) * ((Matches!$E$2:$E$200=I$1)+(Matches!$F$2:$F$200=I$1)) * Matches!$H$2:$H$200 ) &")"} -> 2 (26)
... A17: ="R"&TEXT(B17,"yyyymmdd")&"-"&COUNTIFS($B:$B,B17,$C:$C,"<="&C17) -> R20260203-3 | B17: 46056 | C17: 0.875 | D17: 0.96875 | E17: =MOD(D17 - C17, 1) -> 0.09375 | F17: {=COUNTIFS( Matches!$A$2:$A$200,$A17, Matches!$I$2:$I$200,"*"&F$1&"*" ) &" ("& SUMPRODUCT( (Matches!$A$2:$A$200=$A17) * ((Matches!$C$2:$C$200=F$1)+(Matches!$D$2:$D$200=F$1)) * Matches!$G$2:$G$200 ) + SUMPRODUCT( (Matches!$A$2:$A$200=$A17) * ((Matches!$E$2:$E$200=F$1)+(Matches!$F$2:$F$200=F$1)) * Matches!$H$2:$H$200 ) &")"} -> 3 (30) | G17: {=COUNTIFS( Matches!$A$2:$A$200,$A17, Matches!$I$2:$I$200,"*"&G$1&"*" ) &" ("& SUMPRODUCT( (Matches!$A$2:$A$200=$A17) * ((Matches!$C$2:$C$200=G$1)+(Matches!$D$2:$D$200=G$1)) * Matches!$G$2:$G$200 ) + SUMPRODUCT( (Matches!$A$2:$A$200=$A17) * ((Matches!$E$2:$E$200=G$1)+(Matches!$F$2:$F$200=G$1)) * Matches!$H$2:$H$200 ) &")"} -> 1 (17) | H17: {=COUNTIFS( Matches!$A$2:$A$200,$A17, Matches!$I$2:$I$200,"*"&H$1&"*" ) &" ("& SUMPRODUCT( (Matches!$A$2:$A$200=$A17) * ((Matches!$C$2:$C$200=H$1)+(Matches!$D$2:$D$200=H$1)) * Matches!$G$2:$G$200 ) + SUMPRODUCT( (Matches!$A$2:$A$200=$A17) * ((Matches!$E$2:$E$200=H$1)+(Matches!$F$2:$F$200=H$1)) * Matches!$H$2:$H$200 ) &")"} -> 1 (20) | I17: {=COUNTIFS( Matches!$A$2:$A$200,$A17, Matches!$I$2:$I$200,"*"&I$1&"*" ) &" ("& SUMPRODUCT( (Matches!$A$2:$A$200=$A17) * ((Matches!$C$2:$C$200=I$1)+(Matches!$D$2:$D$200=I$1)) * Matches!$G$2:$G$200 ) + SUMPRODUCT( (Matches!$A$2:$A$200=$A17) * ((Matches!$E$2:$E$200=I$1)+(Matches!$F$2:$F$200=I$1)) * Matches!$H$2:$H$200 ) &")"} -> 1 (21)
A18: ="R"&TEXT(B18,"yyyymmdd")&"-"&COUNTIFS($B:$B,B18,$C:$C,"<="&C18) -> R20260216-1 | B18: 46069 | C18: 0 | E18: =MOD(D18 - C18, 1) -> 0 | F18: {=COUNTIFS( Matches!$A$2:$A$200,$A18, Matches!$I$2:$I$200,"*"&F$1&"*" ) &" ("& SUMPRODUCT( (Matches!$A$2:$A$200=$A18) * ((Matches!$C$2:$C$200=F$1)+(Matches!$D$2:$D$200=F$1)) * Matches!$G$2:$G$200 ) + SUMPRODUCT( (Matches!$A$2:$A$200=$A18) * ((Matches!$E$2:$E$200=F$1)+(Matches!$F$2:$F$200=F$1)) * Matches!$H$2:$H$200 ) &")"} -> 3 (30) | G18: {=COUNTIFS( Matches!$A$2:$A$200,$A18, Matches!$I$2:$I$200,"*"&G$1&"*" ) &" ("& SUMPRODUCT( (Matches!$A$2:$A$200=$A18) * ((Matches!$C$2:$C$200=G$1)+(Matches!$D$2:$D$200=G$1)) * Matches!$G$2:$G$200 ) + SUMPRODUCT( (Matches!$A$2:$A$200=$A18) * ((Matches!$E$2:$E$200=G$1)+(Matches!$F$2:$F$200=G$1)) * Matches!$H$2:$H$200 ) &")"} -> 1 (16) | H18: {=COUNTIFS( Matches!$A$2:$A$200,$A18, Matches!$I$2:$I$200,"*"&H$1&"*" ) &" ("& SUMPRODUCT( (Matches!$A$2:$A$200=$A18) * ((Matches!$C$2:$C$200=H$1)+(Matches!$D$2:$D$200=H$1)) * Matches!$G$2:$G$200 ) + SUMPRODUCT( (Matches!$A$2:$A$200=$A18) * ((Matches!$E$2:$E$200=H$1)+(Matches!$F$2:$F$200=H$1)) * Matches!$H$2:$H$200 ) &")"} -> 1 (16) | I18: {=COUNTIFS( Matches!$A$2:$A$200,$A18, Matches!$I$2:$I$200,"*"&I$1&"*" ) &" ("& SUMPRODUCT( (Matches!$A$2:$A$200=$A18) * ((Matches!$C$2:$C$200=I$1)+(Matches!$D$2:$D$200=I$1)) * Matches!$G$2:$G$200 ) + SUMPRODUCT( (Matches!$A$2:$A$200=$A18) * ((Matches!$E$2:$E$200=I$1)+(Matches!$F$2:$F$200=I$1)) * Matches!$H$2:$H$200 ) &")"} -> 1 (16)
A19: ="R"&TEXT(B19,"yyyymmdd")&"-"&COUNTIFS($B:$B,B19,$C:$C,"<="&C19) -> R20260216-2 | B19: 46069 | C19: 0.041666667 | E19: =MOD(D19 - C19, 1) -> 0.95833333 | F19: {=COUNTIFS( Matches!$A$2:$A$200,$A19, Matches!$I$2:$I$200,"*"&F$1&"*" ) &" ("& SUMPRODUCT( (Matches!$A$2:$A$200=$A19) * ((Matches!$C$2:$C$200=F$1)+(Matches!$D$2:$D$200=F$1)) * Matches!$G$2:$G$200 ) + SUMPRODUCT( (Matches!$A$2:$A$200=$A19) * ((Matches!$E$2:$E$200=F$1)+(Matches!$F$2:$F$200=F$1)) * Matches!$H$2:$H$200 ) &")"} -> 1 (18) | G19: {=COUNTIFS( Matches!$A$2:$A$200,$A19, Matches!$I$2:$I$200,"*"&G$1&"*" ) &" ("& SUMPRODUCT( (Matches!$A$2:$A$200=$A19) * ((Matches!$C$2:$C$200=G$1)+(Matches!$D$2:$D$200=G$1)) * Matches!$G$2:$G$200 ) + SUMPRODUCT( (Matches!$A$2:$A$200=$A19) * ((Matches!$E$2:$E$200=G$1)+(Matches!$F$2:$F$200=G$1)) * Matches!$H$2:$H$200 ) &")"} -> 1 (18) | H19: {=COUNTIFS( Matches!$A$2:$A$200,$A19, Matches!$I$2:$I$200,"*"&H$1&"*" ) &" ("& SUMPRODUCT( (Matches!$A$2:$A$200=$A19) * ((Matches!$C$2:$C$200=H$1)+(Matches!$D$2:$D$200=H$1)) * Matches!$G$2:$G$200 ) + SUMPRODUCT( (Matches!$A$2:$A$200=$A19) * ((Matches!$E$2:$E$200=H$1)+(Matches!$F$2:$F$200=H$1)) * Matches!$H$2:$H$200 ) &")"} -> 1 (22) | I19: {=COUNTIFS( Matches!$A$2:$A$200,$A19, Matches!$I$2:$I$200,"*"&I$1&"*" ) &" ("& SUMPRODUCT( (Matches!$A$2:$A$200=$A19) * ((Matches!$C$2:$C$200=I$1)+(Matches!$D$2:$D$200=I$1)) * Matches!$G$2:$G$200 ) + SUMPRODUCT( (Matches!$A$2:$A$200=$A19) * ((Matches!$E$2:$E$200=I$1)+(Matches!$F$2:$F$200=I$1)) * Matches!$H$2:$H$200 ) &")"} -> 3 (30)
A20: ="R"&TEXT(B20,"yyyymmdd")&"-"&COUNTIFS($B:$B,B20,$C:$C,"<="&C20) -> R20260216-3 | B20: 46069 | C20: 0.083333333 | E20: =MOD(D20 - C20, 1) -> 0.91666667 | F20: {=COUNTIFS( Matches!$A$2:$A$200,$A20, Matches!$I$2:$I$200,"*"&F$1&"*" ) &" ("& SUMPRODUCT( (Matches!$A$2:$A$200=$A20) * ((Matches!$C$2:$C$200=F$1)+(Matches!$D$2:$D$200=F$1)) * Matches!$G$2:$G$200 ) + SUMPRODUCT( (Matches!$A$2:$A$200=$A20) * ((Matches!$E$2:$E$200=F$1)+(Matches!$F$2:$F$200=F$1)) * Matches!$H$2:$H$200 ) &")"} -> 0 (3) | G20: {=COUNTIFS( Matches!$A$2:$A$200,$A20, Matches!$I$2:$I$200,"*"&G$1&"*" ) &" ("& SUMPRODUCT( (Matches!$A$2:$A$200=$A20) * ((Matches!$C$2:$C$200=G$1)+(Matches!$D$2:$D$200=G$1)) * Matches!$G$2:$G$200 ) + SUMPRODUCT( (Matches!$A$2:$A$200=$A20) * ((Matches!$E$2:$E$200=G$1)+(Matches!$F$2:$F$200=G$1)) * Matches!$H$2:$H$200 ) &")"} -> 1 (11) | H20: {=COUNTIFS( Matches!$A$2:$A$200,$A20, Matches!$I$2:$I$200,"*"&H$1&"*" ) &" ("& SUMPRODUCT( (Matches!$A$2:$A$200=$A20) * ((Matches!$C$2:$C$200=H$1)+(Matches!$D$2:$D$200=H$1)) * Matches!$G$2:$G$200 ) + SUMPRODUCT( (Matches!$A$2:$A$200=$A20) * ((Matches!$E$2:$E$200=H$1)+(Matches!$F$2:$F$200=H$1)) * Matches!$H$2:$H$200 ) &")"} -> 1 (12) | I20: {=COUNTIFS( Matches!$A$2:$A$200,$A20, Matches!$I$2:$I$200,"*"&I$1&"*" ) &" ("& SUMPRODUCT( (Matches!$A$2:$A$200=$A20) * ((Matches!$C$2:$C$200=I$1)+(Matches!$D$2:$D$200=I$1)) * Matches!$G$2:$G$200 ) + SUMPRODUCT( (Matches!$A$2:$A$200=$A20) * ((Matches!$E$2:$E$200=I$1)+(Matches!$F$2:$F$200=I$1)) * Matches!$H$2:$H$200 ) &")"} -> 2 (20) | J20: Incomplete revolution (2 sets only)
A21: ="R"&TEXT(B21,"yyyymmdd")&"-"&COUNTIFS($B:$B,B21,$C:$C,"<="&C21) -> R20260312-1 | B21: 46093 | C21: 0 | E21: =MOD(D21 - C21, 1) -> 0 | F21: {=COUNTIFS( Matches!$A$2:$A$200,$A21, Matches!$I$2:$I$200,"*"&F$1&"*" ) &" ("& SUMPRODUCT( (Matches!$A$2:$A$200=$A21) * ((Matches!$C$2:$C$200=F$1)+(Matches!$D$2:$D$200=F$1)) * Matches!$G$2:$G$200 ) + SUMPRODUCT( (Matches!$A$2:$A$200=$A21) * ((Matches!$E$2:$E$200=F$1)+(Matches!$F$2:$F$200=F$1)) * Matches!$H$2:$H$200 ) &")"} -> 0 (17) | G21: {=COUNTIFS( Matches!$A$2:$A$200,$A21, Matches!$I$2:$I$200,"*"&G$1&"*" ) &" ("& SUMPRODUCT( (Matches!$A$2:$A$200=$A21) * ((Matches!$C$2:$C$200=G$1)+(Matches!$D$2:$D$200=G$1)) * Matches!$G$2:$G$200 ) + SUMPRODUCT( (Matches!$A$2:$A$200=$A21) * ((Matches!$E$2:$E$200=G$1)+(Matches!$F$2:$F$200=G$1)) * Matches!$H$2:$H$200 ) &")"} -> 2 (26) | H21: {=COUNTIFS( Matches!$A$2:$A$200,$A21, Matches!$I$2:$I$200,"*"&H$1&"*" ) &" ("& SUMPRODUCT( (Matches!$A$2:$A$200=$A21) * ((Matches!$C$2:$C$200=H$1)+(Matches!$D$2:$D$200=H$1)) * Matches!$G$2:$G$200 ) + SUMPRODUCT( (Matches!$A$2:$A$200=$A21) * ((Matches!$E$2:$E$200=H$1)+(Matches!$F$2:$F$200=H$1)) * Matches!$H$2:$H$200 ) &")"} -> 2 (24) | I21: {=COUNTIFS( Matches!$A$2:$A$200,$A21, Matches!$I$2:$I$200,"*"&I$1&"*" ) &" ("& SUMPRODUCT( (Matches!$A$2:$A$200=$A21) * ((Matches!$C$2:$C$200=I$1)+(Matches!$D$2:$D$200=I$1)) * Matches!$G$2:$G$200 ) + SUMPRODUCT( (Matches!$A$2:$A$200=$A21) * ((Matches!$E$2:$E$200=I$1)+(Matches!$F$2:$F$200=I$1)) * Matches!$H$2:$H$200 ) &")"} -> 2 (27)
A22: ="R"&TEXT(B22,"yyyymmdd")&"-"&COUNTIFS($B:$B,B22,$C:$C,"<="&C22) -> R20260318-1 | B22: 46099 | C22: 0 | E22: =MOD(D22 - C22, 1) -> 0 | F22: {=COUNTIFS( Matches!$A$2:$A$200,$A22, Matches!$I$2:$I$200,"*"&F$1&"*" ) &" ("& SUMPRODUCT( (Matches!$A$2:$A$200=$A22) * ((Matches!$C$2:$C$200=F$1)+(Matches!$D$2:$D$200=F$1)) * Matches!$G$2:$G$200 ) + SUMPRODUCT( (Matches!$A$2:$A$200=$A22) * ((Matches!$E$2:$E$200=F$1)+(Matches!$F$2:$F$200=F$1)) * Matches!$H$2:$H$200 ) &")"} -> 1 (22) | G22: {=COUNTIFS( Matches!$A$2:$A$200,$A22, Matches!$I$2:$I$200,"*"&G$1&"*" ) &" ("& SUMPRODUCT( (Matches!$A$2:$A$200=$A22) * ((Matches!$C$2:$C$200=G$1)+(Matches!$D$2:$D$200=G$1)) * Matches!$G$2:$G$200 ) + SUMPRODUCT( (Matches!$A$2:$A$200=$A22) * ((Matches!$E$2:$E$200=G$1)+(Matches!$F$2:$F$200=G$1)) * Matches!$H$2:$H$200 ) &")"} -> 3 (30) | H22: {=COUNTIFS( Matches!$A$2:$A$200,$A22, Matches!$I$2:$I$200,"*"&H$1&"*" ) &" ("& SUMPRODUCT( (Matches!$A$2:$A$200=$A22) * ((Matches!$C$2:$C$200=H$1)+(Matches!$D$2:$D$200=H$1)) * Matches!$G$2:$G$200 ) + SUMPRODUCT( (Matches!$A$2:$A$200=$A22) * ((Matches!$E$2:$E$200=H$1)+(Matches!$F$2:$F$200=H$1)) * Matches!$H$2:$H$200 ) &")"} -> 1 (18) | I22: {=COUNTIFS( Matches!$A$2:$A$200,$A22, Matches!$I$2:$I$200,"*"&I$1&"*" ) &" ("& SUMPRODUCT( (Matches!$A$2:$A$200=$A22) * ((Matches!$C$2:$C$200=I$1)+(Matches!$D$2:$D$200=I$1)) * Matches!$G$2:$G$200 ) + SUMPRODUCT( (Matches!$A$2:$A$200=$A22) * ((Matches!$E$2:$E$200=I$1)+(Matches!$F$2:$F$200=I$1)) * Matches!$H$2:$H$200 ) &")"} -> 1 (22)
A23: ="R"&TEXT(B23,"yyyymmdd")&"-"&COUNTIFS($B:$B,B23,$C:$C,"<="&C23) -> R20260318-2 | B23: 46099 | C23: 0.041666667 | E23: =MOD(D23 - C23, 1) -> 0.95833333 | F23: {=COUNTIFS( Matches!$A$2:$A$200,$A23, Matches!$I$2:$I$200,"*"&F$1&"*" ) &" ("& SUMPRODUCT( (Matches!$A$2:$A$200=$A23) * ((Matches!$C$2:$C$200=F$1)+(Matches!$D$2:$D$200=F$1)) * Matches!$G$2:$G$200 ) + SUMPRODUCT( (Matches!$A$2:$A$200=$A23) * ((Matches!$E$2:$E$200=F$1)+(Matches!$F$2:$F$200=F$1)) * Matches!$H$2:$H$200 ) &")"} -> 1 (22) | G23: {=COUNTIFS( Matches!$A$2:$A$200,$A23, Matches!$I$2:$I$200,"*"&G$1&"*" ) &" ("& SUMPRODUCT( (Matches!$A$2:$A$200=$A23) * ((Matches!$C$2:$C$200=G$1)+(Matches!$D$2:$D$200=G$1)) * Matches!$G$2:$G$200 ) + SUMPRODUCT( (Matches!$A$2:$A$200=$A23) * ((Matches!$E$2:$E$200=G$1)+(Matches!$F$2:$F$200=G$1)) * Matches!$H$2:$H$200 ) &")"} -> 3 (30) | H23: {=COUNTIFS( Matches!$A$2:$A$200,$A23, Matches!$I$2:$I$200,"*"&H$1&"*" ) &" ("& SUMPRODUCT( (Matches!$A$2:$A$200=$A23) * ((Matches!$C$2:$C$200=H$1)+(Matches!$D$2:$D$200=H$1)) * Matches!$G$2:$G$200 ) + SUMPRODUCT( (Matches!$A$2:$A$200=$A23) * ((Matches!$E$2:$E$200=H$1)+(Matches!$F$2:$F$200=H$1)) * Matches!$H$2:$H$200 ) &")"} -> 1 (22) | I23: {=COUNTIFS( Matches!$A$2:$A$200,$A23, Matches!$I$2:$I$200,"*"&I$1&"*" ) &" ("& SUMPRODUCT( (Matches!$A$2:$A$200=$A23) * ((Matches!$C$2:$C$200=I$1)+(Matches!$D$2:$D$200=I$1)) * Matches!$G$2:$G$200 ) + SUMPRODUCT( (Matches!$A$2:$A$200=$A23) * ((Matches!$E$2:$E$200=I$1)+(Matches!$F$2:$F$200=I$1)) * Matches!$H$2:$H$200 ) &")"} -> 1 (16)
A24: ="R"&TEXT(B24,"yyyymmdd")&"-"&COUNTIFS($B:$B,B24,$C:$C,"<="&C24) -> R20260318-3 | B24: 46099 | C24: 0.083333333 | E24: =MOD(D24 - C24, 1) -> 0.91666667 | F24: {=COUNTIFS( Matches!$A$2:$A$200,$A24, Matches!$I$2:$I$200,"*"&F$1&"*" ) &" ("& SUMPRODUCT( (Matches!$A$2:$A$200=$A24) * ((Matches!$C$2:$C$200=F$1)+(Matches!$D$2:$D$200=F$1)) * Matches!$G$2:$G$200 ) + SUMPRODUCT( (Matches!$A$2:$A$200=$A24) * ((Matches!$E$2:$E$200=F$1)+(Matches!$F$2:$F$200=F$1)) * Matches!$H$2:$H$200 ) &")"} -> 1 (25) | G24: {=COUNTIFS( Matches!$A$2:$A$200,$A24, Matches!$I$2:$I$200,"*"&G$1&"*" ) &" ("& SUMPRODUCT( (Matches!$A$2:$A$200=$A24) * ((Matches!$C$2:$C$200=G$1)+(Matches!$D$2:$D$200=G$1)) * Matches!$G$2:$G$200 ) + SUMPRODUCT( (Matches!$A$2:$A$200=$A24) * ((Matches!$E$2:$E$200=G$1)+(Matches!$F$2:$F$200=G$1)) * Matches!$H$2:$H$200 ) &")"} -> 1 (20) | H24: {=COUNTIFS( Matches!$A$2:$A$200,$A24, Matches!$I$2:$I$200,"*"&H$1&"*" ) &" ("& SUMPRODUCT( (Matches!$A$2:$A$200=$A24) * ((Matches!$C$2:$C$200=H$1)+(Matches!$D$2:$D$200=H$1)) * Matches!$G$2:$G$200 ) + SUMPRODUCT( (Matches!$A$2:$A$200=$A24) * ((Matches!$E$2:$E$200=H$1)+(Matches!$F$2:$F$200=H$1)) * Matches!$H$2:$H$200 ) &")"} -> 3 (30) | I24: {=COUNTIFS( Matches!$A$2:$A$200,$A24, Matches!$I$2:$I$200,"*"&I$1&"*" ) &" ("& SUMPRODUCT( (Matches!$A$2:$A$200=$A24) * ((Matches!$C$2:$C$200=I$1)+(Matches!$D$2:$D$200=I$1)) * Matches!$G$2:$G$200 ) + SUMPRODUCT( (Matches!$A$2:$A$200=$A24) * ((Matches!$E$2:$E$200=I$1)+(Matches!$F$2:$F$200=I$1)) * Matches!$H$2:$H$200 ) &")"} -> 1 (23)
A25: R20260403-1 | B25: 46115 | C25: 0 | E25: =MOD(D25 - C25, 1) -> 0 | F25: {=COUNTIFS( Matches!$A$2:$A$200,$A25, Matches!$I$2:$I$200,"*"&F$1&"*" ) &" ("& SUMPRODUCT( (Matches!$A$2:$A$200=$A25) * ((Matches!$C$2:$C$200=F$1)+(Matches!$D$2:$D$200=F$1)) * Matches!$G$2:$G$200 ) + SUMPRODUCT( (Matches!$A$2:$A$200=$A25) * ((Matches!$E$2:$E$200=F$1)+(Matches!$F$2:$F$200=F$1)) * Matches!$H$2:$H$200 ) &")"} -> 2 (22) | G25: {=COUNTIFS( Matches!$A$2:$A$200,$A25, Matches!$I$2:$I$200,"*"&G$1&"*" ) &" ("& SUMPRODUCT( (Matches!$A$2:$A$200=$A25) * ((Matches!$C$2:$C$200=G$1)+(Matches!$D$2:$D$200=G$1)) * Matches!$G$2:$G$200 ) + SUMPRODUCT( (Matches!$A$2:$A$200=$A25) * ((Matches!$E$2:$E$200=G$1)+(Matches!$F$2:$F$200=G$1)) * Matches!$H$2:$H$200 ) &")"} -> 0 (18) | H25: {=COUNTIFS( Matches!$A$2:$A$200,$A25, Matches!$I$2:$I$200,"*"&H$1&"*" ) &" ("& SUMPRODUCT( (Matches!$A$2:$A$200=$A25) * ((Matches!$C$2:$C$200=H$1)+(Matches!$D$2:$D$200=H$1)) * Matches!$G$2:$G$200 ) + SUMPRODUCT( (Matches!$A$2:$A$200=$A25) * ((Matches!$E$2:$E$200=H$1)+(Matches!$F$2:$F$200=H$1)) * Matches!$H$2:$H$200 ) &")"} -> 2 (29) | I25: {=COUNTIFS( Matches!$A$2:$A$200,$A25, Matches!$I$2:$I$200,"*"&I$1&"*" ) &" ("& SUMPRODUCT( (Matches!$A$2:$A$200=$A25) * ((Matches!$C$2:$C$200=I$1)+(Matches!$D$2:$D$200=I$1)) * Matches!$G$2:$G$200 ) + SUMPRODUCT( (Matches!$A$2:$A$200=$A25) * ((Matches!$E$2:$E$200=I$1)+(Matches!$F$2:$F$200=I$1)) * Matches!$H$2:$H$200 ) &")"} -> 2 (27)
A26: R20260403-2 | B26: 46115 | C26: 0.041666667 | E26: =MOD(D26 - C26, 1) -> 0.95833333 | F26: {=COUNTIFS( Matches!$A$2:$A$200,$A26, Matches!$I$2:$I$200,"*"&F$1&"*" ) &" ("& SUMPRODUCT( (Matches!$A$2:$A$200=$A26) * ((Matches!$C$2:$C$200=F$1)+(Matches!$D$2:$D$200=F$1)) * Matches!$G$2:$G$200 ) + SUMPRODUCT( (Matches!$A$2:$A$200=$A26) * ((Matches!$E$2:$E$200=F$1)+(Matches!$F$2:$F$200=F$1)) * Matches!$H$2:$H$200 ) &")"} -> 1 (18) | G26: {=COUNTIFS( Matches!$A$2:$A$200,$A26, Matches!$I$2:$I$200,"*"&G$1&"*" ) &" ("& SUMPRODUCT( (Matches!$A$2:$A$200=$A26) * ((Matches!$C$2:$C$200=G$1)+(Matches!$D$2:$D$200=G$1)) * Matches!$G$2:$G$200 ) + SUMPRODUCT( (Matches!$A$2:$A$200=$A26) * ((Matches!$E$2:$E$200=G$1)+(Matches!$F$2:$F$200=G$1)) * Matches!$H$2:$H$200 ) &")"} -> 1 (17) | H26: {=COUNTIFS( Matches!$A$2:$A$200,$A26, Matches!$I$2:$I$200,"*"&H$1&"*" ) &" ("& SUMPRODUCT( (Matches!$A$2:$A$200=$A26) * ((Matches!$C$2:$C$200=H$1)+(Matches!$D$2:$D$200=H$1)) * Matches!$G$2:$G$200 ) + SUMPRODUCT( (Matches!$A$2:$A$200=$A26) * ((Matches!$E$2:$E$200=H$1)+(Matches!$F$2:$F$200=H$1)) * Matches!$H$2:$H$200 ) &")"} -> 3 (30) | I26: {=COUNTIFS( Matches!$A$2:$A$200,$A26, Matches!$I$2:$I$200,"*"&I$1&"*" ) &" ("& SUMPRODUCT( (Matches!$A$2:$A$200=$A26) * ((Matches!$C$2:$C$200=I$1)+(Matches!$D$2:$D$200=I$1)) * Matches!$G$2:$G$200 ) + SUMPRODUCT( (Matches!$A$2:$A$200=$A26) * ((Matches!$E$2:$E$200=I$1)+(Matches!$F$2:$F$200=I$1)) * Matches!$H$2:$H$200 ) &")"} -> 1 (25)
A27: ="R"&TEXT(B27,"yyyymmdd")&"-"&COUNTIFS($B:$B,B27,$C:$C,"<="&C27) -> R20260406-1 | B27: 46118 | C27: 0 | E27: =MOD(D27 - C27, 1) -> 0 | F27: {=COUNTIFS( Matches!$A$2:$A$200,$A27, Matches!$I$2:$I$200,"*"&F$1&"*" ) &" ("& SUMPRODUCT( (Matches!$A$2:$A$200=$A27) * ((Matches!$C$2:$C$200=F$1)+(Matches!$D$2:$D$200=F$1)) * Matches!$G$2:$G$200 ) + SUMPRODUCT( (Matches!$A$2:$A$200=$A27) * ((Matches!$E$2:$E$200=F$1)+(Matches!$F$2:$F$200=F$1)) * Matches!$H$2:$H$200 ) &")"} -> 2 (21) | G27: {=COUNTIFS( Matches!$A$2:$A$200,$A27, Matches!$I$2:$I$200,"*"&G$1&"*" ) &" ("& SUMPRODUCT( (Matches!$A$2:$A$200=$A27) * ((Matches!$C$2:$C$200=G$1)+(Matches!$D$2:$D$200=G$1)) * Matches!$G$2:$G$200 ) + SUMPRODUCT( (Matches!$A$2:$A$200=$A27) * ((Matches!$E$2:$E$200=G$1)+(Matches!$F$2:$F$200=G$1)) * Matches!$H$2:$H$200 ) &")"} -> 0 (15) | H27: {=COUNTIFS( Matches!$A$2:$A$200,$A27, Matches!$I$2:$I$200,"*"&H$1&"*" ) &" ("& SUMPRODUCT( (Matches!$A$2:$A$200=$A27) * ((Matches!$C$2:$C$200=H$1)+(Matches!$D$2:$D$200=H$1)) * Matches!$G$2:$G$200 ) + SUMPRODUCT( (Matches!$A$2:$A$200=$A27) * ((Matches!$E$2:$E$200=H$1)+(Matches!$F$2:$F$200=H$1)) * Matches!$H$2:$H$200 ) &")"} -> 2 (29) | I27: {=COUNTIFS( Matches!$A$2:$A$200,$A27, Matches!$I$2:$I$200,"*"&I$1&"*" ) &" ("& SUMPRODUCT( (Matches!$A$2:$A$200=$A27) * ((Matches!$C$2:$C$200=I$1)+(Matches!$D$2:$D$200=I$1)) * Matches!$G$2:$G$200 ) + SUMPRODUCT( (Matches!$A$2:$A$200=$A27) * ((Matches!$E$2:$E$200=I$1)+(Matches!$F$2:$F$200=I$1)) * Matches!$H$2:$H$200 ) &")"} -> 2 (25)
A28: ="R"&TEXT(B28,"yyyymmdd")&"-"&COUNTIFS($B:$B,B28,$C:$C,"<="&C28) -> R20260406-2 | B28: 46118 | C28: 0.041666667 | E28: =MOD(D28 - C28, 1) -> 0.95833333 | F28: {=COUNTIFS( Matches!$A$2:$A$200,$A28, Matches!$I$2:$I$200,"*"&F$1&"*" ) &" ("& SUMPRODUCT( (Matches!$A$2:$A$200=$A28) * ((Matches!$C$2:$C$200=F$1)+(Matches!$D$2:$D$200=F$1)) * Matches!$G$2:$G$200 ) + SUMPRODUCT( (Matches!$A$2:$A$200=$A28) * ((Matches!$E$2:$E$200=F$1)+(Matches!$F$2:$F$200=F$1)) * Matches!$H$2:$H$200 ) &")"} -> 2 (24) | G28: {=COUNTIFS( Matches!$A$2:$A$200,$A28, Matches!$I$2:$I$200,"*"&G$1&"*" ) &" ("& SUMPRODUCT( (Matches!$A$2:$A$200=$A28) * ((Matches!$C$2:$C$200=G$1)+(Matches!$D$2:$D$200=G$1)) * Matches!$G$2:$G$200 ) + SUMPRODUCT( (Matches!$A$2:$A$200=$A28) * ((Matches!$E$2:$E$200=G$1)+(Matches!$F$2:$F$200=G$1)) * Matches!$H$2:$H$200 ) &")"} -> 2 (21) | H28: {=COUNTIFS( Matches!$A$2:$A$200,$A28, Matches!$I$2:$I$200,"*"&H$1&"*" ) &" ("& SUMPRODUCT( (Matches!$A$2:$A$200=$A28) * ((Matches!$C$2:$C$200=H$1)+(Matches!$D$2:$D$200=H$1)) * Matches!$G$2:$G$200 ) + SUMPRODUCT( (Matches!$A$2:$A$200=$A28) * ((Matches!$E$2:$E$200=H$1)+(Matches!$F$2:$F$200=H$1)) * Matches!$H$2:$H$200 ) &")"} -> 0 (14) | I28: {=COUNTIFS( Matches!$A$2:$A$200,$A28, Matches!$I$2:$I$200,"*"&I$1&"*" ) &" ("& SUMPRODUCT( (Matches!$A$2:$A$200=$A28) * ((Matches!$C$2:$C$200=I$1)+(Matches!$D$2:$D$200=I$1)) * Matches!$G$2:$G$200 ) + SUMPRODUCT( (Matches!$A$2:$A$200=$A28) * ((Matches!$E$2:$E$200=I$1)+(Matches!$F$2:$F$200=I$1)) * Matches!$H$2:$H$200 ) &")"} -> 2 (29)
A29: ="R"&TEXT(B29,"yyyymmdd")&"-"&COUNTIFS($B:$B,B29,$C:$C,"<="&C29) -> R20260427-1 | B29: 46139 | C29: 0 | E29: =MOD(D29 - C29, 1) -> 0 | F29: {=COUNTIFS( Matches!$A$2:$A$200,$A29, Matches!$I$2:$I$200,"*"&F$1&"*" ) &" ("& SUMPRODUCT( (Matches!$A$2:$A$200=$A29) * ((Matches!$C$2:$C$200=F$1)+(Matches!$D$2:$D$200=F$1)) * Matches!$G$2:$G$200 ) + SUMPRODUCT( (Matches!$A$2:$A$200=$A29) * ((Matches!$E$2:$E$200=F$1)+(Matches!$F$2:$F$200=F$1)) * Matches!$H$2:$H$200 ) &")"} -> 2 (24) | G29: {=COUNTIFS( Matches!$A$2:$A$200,$A29, Matches!$I$2:$I$200,"*"&G$1&"*" ) &" ("& SUMPRODUCT( (Matches!$A$2:$A$200=$A29) * ((Matches!$C$2:$C$200=G$1)+(Matches!$D$2:$D$200=G$1)) * Matches!$G$2:$G$200 ) + SUMPRODUCT( (Matches!$A$2:$A$200=$A29) * ((Matches!$E$2:$E$200=G$1)+(Matches!$F$2:$F$200=G$1)) * Matches!$H$2:$H$200 ) &")"} -> 2 (29) | H29: {=COUNTIFS( Matches!$A$2:$A$200,$A29, Matches!$I$2:$I$200,"*"&H$1&"*" ) &" ("& SUMPRODUCT( (Matches!$A$2:$A$200=$A29) * ((Matches!$C$2:$C$200=H$1)+(Matches!$D$2:$D$200=H$1)) * Matches!$G$2:$G$200 ) + SUMPRODUCT( (Matches!$A$2:$A$200=$A29) * ((Matches!$E$2:$E$200=H$1)+(Matches!$F$2:$F$200=H$1)) * Matches!$H$2:$H$200 ) &")"} -> 2 (25) | I29: {=COUNTIFS( Matches!$A$2:$A$200,$A29, Matches!$I$2:$I$200,"*"&I$1&"*" ) &" ("& SUMPRODUCT( (Matches!$A$2:$A$200=$A29) * ((Matches!$C$2:$C$200=I$1)+(Matches!$D$2:$D$200=I$1)) * Matches!$G$2:$G$200 ) + SUMPRODUCT( (Matches!$A$2:$A$200=$A29) * ((Matches!$E$2:$E$200=I$1)+(Matches!$F$2:$F$200=I$1)) * Matches!$H$2:$H$200 ) &")"} -> 0 (18)
A30: ="R"&TEXT(B30,"yyyymmdd")&"-"&COUNTIFS($B:$B,B30,$C:$C,"<="&C30) -> R20260427-2 | B30: 46139 | C30: 0.041666667 | E30: =MOD(D30 - C30, 1) -> 0.95833333 | F30: {=COUNTIFS( Matches!$A$2:$A$200,$A30, Matches!$I$2:$I$200,"*"&F$1&"*" ) &" ("& SUMPRODUCT( (Matches!$A$2:$A$200=$A30) * ((Matches!$C$2:$C$200=F$1)+(Matches!$D$2:$D$200=F$1)) * Matches!$G$2:$G$200 ) + SUMPRODUCT( (Matches!$A$2:$A$200=$A30) * ((Matches!$E$2:$E$200=F$1)+(Matches!$F$2:$F$200=F$1)) * Matches!$H$2:$H$200 ) &")"} -> 1 (18) | G30: {=COUNTIFS( Matches!$A$2:$A$200,$A30, Matches!$I$2:$I$200,"*"&G$1&"*" ) &" ("& SUMPRODUCT( (Matches!$A$2:$A$200=$A30) * ((Matches!$C$2:$C$200=G$1)+(Matches!$D$2:$D$200=G$1)) * Matches!$G$2:$G$200 ) + SUMPRODUCT( (Matches!$A$2:$A$200=$A30) * ((Matches!$E$2:$E$200=G$1)+(Matches!$F$2:$F$200=G$1)) * Matches!$H$2:$H$200 ) &")"} -> 3 (30) | H30: {=COUNTIFS( Matches!$A$2:$A$200,$A30, Matches!$I$2:$I$200,"*"&H$1&"*" ) &" ("& SUMPRODUCT( (Matches!$A$2:$A$200=$A30) * ((Matches!$C$2:$C$200=H$1)+(Matches!$D$2:$D$200=H$1)) * Matches!$G$2:$G$200 ) + SUMPRODUCT( (Matches!$A$2:$A$200=$A30) * ((Matches!$E$2:$E$200=H$1)+(Matches!$F$2:$F$200=H$1)) * Matches!$H$2:$H$200 ) &")"} -> 1 (19) | I30: {=COUNTIFS( Matches!$A$2:$A$200,$A30, Matches!$I$2:$I$200,"*"&I$1&"*" ) &" ("& SUMPRODUCT( (Matches!$A$2:$A$200=$A30) * ((Matches!$C$2:$C$200=I$1)+(Matches!$D$2:$D$200=I$1)) * Matches!$G$2:$G$200 ) + SUMPRODUCT( (Matches!$A$2:$A$200=$A30) * ((Matches!$E$2:$E$200=I$1)+(Matches!$F$2:$F$200=I$1)) * Matches!$H$2:$H$200 ) &")"} -> 1 (13)
A31: ="R"&TEXT(B31,"yyyymmdd")&"-"&COUNTIFS($B:$B,B31,$C:$C,"<="&C31) -> R20260529-1 | B31: 46171 | C31: 0.5 | E31: =MOD(D31 - C31, 1) -> 0.5 | F31: {=COUNTIFS( Matches!$A$2:$A$200,$A31, Matches!$I$2:$I$200,"*"&F$1&"*" ) &" ("& SUMPRODUCT( (Matches!$A$2:$A$200=$A31) * ((Matches!$C$2:$C$200=F$1)+(Matches!$D$2:$D$200=F$1)) * Matches!$G$2:$G$200 ) + SUMPRODUCT( (Matches!$A$2:$A$200=$A31) * ((Matches!$E$2:$E$200=F$1)+(Matches!$F$2:$F$200=F$1)) * Matches!$H$2:$H$200 ) &")"} -> 2 (26) | G31: {=COUNTIFS( Matches!$A$2:$A$200,$A31, Matches!$I$2:$I$200,"*"&G$1&"*" ) &" ("& SUMPRODUCT( (Matches!$A$2:$A$200=$A31) * ((Matches!$C$2:$C$200=G$1)+(Matches!$D$2:$D$200=G$1)) * Matches!$G$2:$G$200 ) + SUMPRODUCT( (Matches!$A$2:$A$200=$A31) * ((Matches!$E$2:$E$200=G$1)+(Matches!$F$2:$F$200=G$1)) * Matches!$H$2:$H$200 ) &")"} -> 2 (27) | H31: {=COUNTIFS( Matches!$A$2:$A$200,$A31, Matches!$I$2:$I$200,"*"&H$1&"*" ) &" ("& SUMPRODUCT( (Matches!$A$2:$A$200=$A31) * ((Matches!$C$2:$C$200=H$1)+(Matches!$D$2:$D$200=H$1)) * Matches!$G$2:$G$200 ) + SUMPRODUCT( (Matches!$A$2:$A$200=$A31) * ((Matches!$E$2:$E$200=H$1)+(Matches!$F$2:$F$200=H$1)) * Matches!$H$2:$H$200 ) &")"} -> 2 (27) | I31: {=COUNTIFS( Matches!$A$2:$A$200,$A31, Matches!$I$2:$I$200,"*"&I$1&"*" ) &" ("& SUMPRODUCT( (Matches!$A$2:$A$200=$A31) * ((Matches!$C$2:$C$200=I$1)+(Matches!$D$2:$D$200=I$1)) * Matches!$G$2:$G$200 ) + SUMPRODUCT( (Matches!$A$2:$A$200=$A31) * ((Matches!$E$2:$E$200=I$1)+(Matches!$F$2:$F$200=I$1)) * Matches!$H$2:$H$200 ) &")"} -> 0 (20)
A32: ="R"&TEXT(B32,"yyyymmdd")&"-"&COUNTIFS($B:$B,B32,$C:$C,"<="&C32) -> R20260725-1 | B32: 46228 | C32: 12 | E32: =MOD(D32 - C32, 1) -> 0 | F32: {=COUNTIFS( Matches!$A$2:$A$200,$A32, Matches!$I$2:$I$200,"*"&F$1&"*" ) &" ("& SUMPRODUCT( (Matches!$A$2:$A$200=$A32) * ((Matches!$C$2:$C$200=F$1)+(Matches!$D$2:$D$200=F$1)) * Matches!$G$2:$G$200 ) + SUMPRODUCT( (Matches!$A$2:$A$200=$A32) * ((Matches!$E$2:$E$200=F$1)+(Matches!$F$2:$F$200=F$1)) * Matches!$H$2:$H$200 ) &")"} -> 2 (27) | G32: {=COUNTIFS( Matches!$A$2:$A$200,$A32, Matches!$I$2:$I$200,"*"&G$1&"*" ) &" ("& SUMPRODUCT( (Matches!$A$2:$A$200=$A32) * ((Matches!$C$2:$C$200=G$1)+(Matches!$D$2:$D$200=G$1)) * Matches!$G$2:$G$200 ) + SUMPRODUCT( (Matches!$A$2:$A$200=$A32) * ((Matches!$E$2:$E$200=G$1)+(Matches!$F$2:$F$200=G$1)) * Matches!$H$2:$H$200 ) &")"} -> 2 (26) | H32: {=COUNTIFS( Matches!$A$2:$A$200,$A32, Matches!$I$2:$I$200,"*"&H$1&"*" ) &" ("& SUMPRODUCT( (Matches!$A$2:$A$200=$A32) * ((Matches!$C$2:$C$200=H$1)+(Matches!$D$2:$D$200=H$1)) * Matches!$G$2:$G$200 ) + SUMPRODUCT( (Matches!$A$2:$A$200=$A32) * ((Matches!$E$2:$E$200=H$1)+(Matches!$F$2:$F$200=H$1)) * Matches!$H$2:$H$200 ) &")"} -> 2 (26) | I32: {=COUNTIFS( Matches!$A$2:$A$200,$A32, Matches!$I$2:$I$200,"*"&I$1&"*" ) &" ("& SUMPRODUCT( (Matches!$A$2:$A$200=$A32) * ((Matches!$C$2:$C$200=I$1)+(Matches!$D$2:$D$200=I$1)) * Matches!$G$2:$G$200 ) + SUMPRODUCT( (Matches!$A$2:$A$200=$A32) * ((Matches!$E$2:$E$200=I$1)+(Matches!$F$2:$F$200=I$1)) * Matches!$H$2:$H$200 ) &")"} -> 0 (19) | J32: SEASON 2 START
A33: R20260903-1 | B33: 46268 | F33: {=COUNTIFS( Matches!$A$2:$A$200,$A33, Matches!$I$2:$I$200,"*"&F$1&"*" ) &" ("& SUMPRODUCT( (Matches!$A$2:$A$200=$A33) * ((Matches!$C$2:$C$200=F$1)+(Matches!$D$2:$D$200=F$1)) * Matches!$G$2:$G$200 ) + SUMPRODUCT( (Matches!$A$2:$A$200=$A33) * ((Matches!$E$2:$E$200=F$1)+(Matches!$F$2:$F$200=F$1)) * Matches!$H$2:$H$200 ) &")"} -> 0 (14) | G33: {=COUNTIFS( Matches!$A$2:$A$200,$A33, Matches!$I$2:$I$200,"*"&G$1&"*" ) &" ("& SUMPRODUCT( (Matches!$A$2:$A$200=$A33) * ((Matches!$C$2:$C$200=G$1)+(Matches!$D$2:$D$200=G$1)) * Matches!$G$2:$G$200 ) + SUMPRODUCT( (Matches!$A$2:$A$200=$A33) * ((Matches!$E$2:$E$200=G$1)+(Matches!$F$2:$F$200=G$1)) * Matches!$H$2:$H$200 ) &")"} -> 2 (20) | H33: {=COUNTIFS( Matches!$A$2:$A$200,$A33, Matches!$I$2:$I$200,"*"&H$1&"*" ) &" ("& SUMPRODUCT( (Matches!$A$2:$A$200=$A33) * ((Matches!$C$2:$C$200=H$1)+(Matches!$D$2:$D$200=H$1)) * Matches!$G$2:$G$200 ) + SUMPRODUCT( (Matches!$A$2:$A$200=$A33) * ((Matches!$E$2:$E$200=H$1)+(Matches!$F$2:$F$200=H$1)) * Matches!$H$2:$H$200 ) &")"} -> 1 (18) | I33: {=COUNTIFS( Matches!$A$2:$A$200,$A33, Matches!$I$2:$I$200,"*"&I$1&"*" ) &" ("& SUMPRODUCT( (Matches!$A$2:$A$200=$A33) * ((Matches!$C$2:$C$200=I$1)+(Matches!$D$2:$D$200=I$1)) * Matches!$G$2:$G$200 ) + SUMPRODUCT( (Matches!$A$2:$A$200=$A33) * ((Matches!$E$2:$E$200=I$1)+(Matches!$F$2:$F$200=I$1)) * Matches!$H$2:$H$200 ) &")"} -> 1 (16)

Sheet Matches
A1: RevolutionID | B1: SetNo | C1: TeamA_P1 | D1: TeamA_P2 | E1: TeamB_P1 | F1: TeamB_P2 | G1: ScoreA | H1: ScoreB | I1: Winner | J1: Notes | K1: SetID
A2: R20251201-1 | B2: =COUNTIF($A$2:A2, A2) -> 1 | C2: LX | D2: VM | E2: MN | F2: ML | G2: 6 | H2: 10 | I2: =IF(G2>H2, IF(C2<D2, C2&"/"&D2, D2&"/"&C2), IF(E2<F2, E2&"/"&F2, F2&"/"&E2) ) -> ML/MN | K2: =_xlfn.CONCAT(A2, "-", B2) -> R20251201-1-1
A3: R20251201-1 | B3: =COUNTIF($A$2:A3, A3) -> 2 | C3: VM | D3: ML | E3: MN | F3: LX | G3: 5 | H3: 10 | I3: =IF(G3>H3, IF(C3<D3, C3&"/"&D3, D3&"/"&C3), IF(E3<F3, E3&"/"&F3, F3&"/"&E3) ) -> LX/MN | K3: =_xlfn.CONCAT(A3, "-", B3) -> R20251201-1-2
A4: R20251201-1 | B4: =COUNTIF($A$2:A4, A4) -> 3 | C4: MN | D4: VM | E4: ML | F4: LX | G4: 3 | H4: 10 | I4: =IF(G4>H4, IF(C4<D4, C4&"/"&D4, D4&"/"&C4), IF(E4<F4, E4&"/"&F4, F4&"/"&E4) ) -> LX/ML | K4: =_xlfn.CONCAT(A4, "-", B4) -> R20251201-1-3
A5: R20251215-1 | B5: =COUNTIF($A$2:A5, A5) -> 1 | C5: VM | D5: MN | E5: ML | F5: LX | G5: 9 | H5: 10 | I5: =IF(G5>H5, IF(C5<D5, C5&"/"&D5, D5&"/"&C5), IF(E5<F5, E5&"/"&F5, F5&"/"&E5) ) -> LX/ML | K5: =_xlfn.CONCAT(A5, "-", B5) -> R20251215-1-1
A6: R20251215-1 | B6: =COUNTIF($A$2:A6, A6) -> 2 | C6: VM | D6: LX | E6: ML | F6: MN | G6: 9 | H6: 10 | I6: =IF(G6>H6, IF(C6<D6, C6&"/"&D6, D6&"/"&C6), IF(E6<F6, E6&"/"&F6, F6&"/"&E6) ) -> ML/MN | K6: =_xlfn.CONCAT(A6, "-", B6) -> R20251215-1-2
A7: R20251215-1 | B7: =COUNTIF($A$2:A7, A7) -> 3 | C7: LX | D7: MN | E7: ML | F7: VM | G7: 3 | H7: 10 | I7: =IF(G7>H7, IF(C7<D7, C7&"/"&D7, D7&"/"&C7), IF(E7<F7, E7&"/"&F7, F7&"/"&E7) ) -> ML/VM | K7: =_xlfn.CONCAT(A7, "-", B7) -> R20251215-1-3
A8: R20251229-1 | B8: =COUNTIF($A$2:A8, A8) -> 1 | C8: MN | D8: LX | E8: ML | F8: VM | G8: 9 | H8: 10 | I8: =IF(G8>H8, IF(C8<D8, C8&"/"&D8, D8&"/"&C8), IF(E8<F8, E8&"/"&F8, F8&"/"&E8) ) -> ML/VM | K8: =_xlfn.CONCAT(A8, "-", B8) -> R20251229-1-1
A9: R20251229-1 | B9: =COUNTIF($A$2:A9, A9) -> 2 | C9: ML | D9: LX | E9: VM | F9: MN | G9: 2 | H9: 10 | I9: =IF(G9>H9, IF(C9<D9, C9&"/"&D9, D9&"/"&C9), IF(E9<F9, E9&"/"&F9, F9&"/"&E9) ) -> MN/VM | K9: =_xlfn.CONCAT(A9, "-", B9) -> R20251229-1-2
A10: R20251229-1 | B10: =COUNTIF($A$2:A10, A10) -> 3 | C10: VM | D10: LX | E10: ML | F10: MN | G10: 6 | H10: 10 | I10: =IF(G10>H10, IF(C10<D10, C10&"/"&D10, D10&"/"&C10), IF(E10<F10, E10&"/"&F10, F10&"/"&E10) ) -> ML/MN | K10: =_xlfn.CONCAT(A10, "-", B10) -> R20251229-1-3
A11: R20251229-2 | B11: =COUNTIF($A$2:A11, A11) -> 1 | C11: VM | D11: LX | E11: ML | F11: MN | G11: 9 | H11: 10 | I11: =IF(G11>H11, IF(C11<D11, C11&"/"&D11, D11&"/"&C11), IF(E11<F11, E11&"/"&F11, F11&"/"&E11) ) -> ML/MN | K11: =_xlfn.CONCAT(A11, "-", B11) -> R20251229-2-1
A12: R20251229-2 | B12: =COUNTIF($A$2:A12, A12) -> 2 | C12: MN | D12: VM | E12: ML | F12: LX | G12: 6 | H12: 10 | I12: =IF(G12>H12, IF(C12<D12, C12&"/"&D12, D12&"/"&C12), IF(E12<F12, E12&"/"&F12, F12&"/"&E12) ) -> LX/ML | K12: =_xlfn.CONCAT(A12, "-", B12) -> R20251229-2-2
A13: R20251229-2 | B13: =COUNTIF($A$2:A13, A13) -> 3 | C13: ML | D13: VM | E13: MN | F13: LX | G13: 5 | H13: 10 | I13: =IF(G13>H13, IF(C13<D13, C13&"/"&D13, D13&"/"&C13), IF(E13<F13, E13&"/"&F13, F13&"/"&E13) ) -> LX/MN | K13: =_xlfn.CONCAT(A13, "-", B13) -> R20251229-2-3
... A25: R20260112-2 | B25: =COUNTIF($A$2:A25, A25) -> 3 | C25: VM | D25: MN | E25: LX | F25: ML | G25: 8 | H25: 10 | I25: =IF(G25>H25, IF(C25<D25, C25&"/"&D25, D25&"/"&C25), IF(E25<F25, E25&"/"&F25, F25&"/"&E25) ) -> LX/ML | K25: =_xlfn.CONCAT(A25, "-", B25) -> R20260112-2-3
A26: R20260119-1 | B26: =COUNTIF($A$2:A26, A26) -> 1 | C26: ML | D26: VM | E26: LX | F26: MN | G26: 2 | H26: 10 | I26: =IF(G26>H26, IF(C26<D26, C26&"/"&D26, D26&"/"&C26), IF(E26<F26, E26&"/"&F26, F26&"/"&E26) ) -> LX/MN | J26: 30m | K26: =_xlfn.CONCAT(A26, "-", B26) -> R20260119-1-1
A27: R20260119-1 | B27: =COUNTIF($A$2:A27, A27) -> 2 | C27: VM | D27: MN | E27: LX | F27: ML | G27: 5 | H27: 10 | I27: =IF(G27>H27, IF(C27<D27, C27&"/"&D27, D27&"/"&C27), IF(E27<F27, E27&"/"&F27, F27&"/"&E27) ) -> LX/ML | J27: 50m | K27: =_xlfn.CONCAT(A27, "-", B27) -> R20260119-1-2
A28: R20260119-1 | B28: =COUNTIF($A$2:A28, A28) -> 3 | C28: VM | D28: LX | E28: MN | F28: ML | G28: 9 | H28: 10 | I28: =IF(G28>H28, IF(C28<D28, C28&"/"&D28, D28&"/"&C28), IF(E28<F28, E28&"/"&F28, F28&"/"&E28) ) -> ML/MN | J28: 45m | K28: =_xlfn.CONCAT(A28, "-", B28) -> R20260119-1-3
A29: R20260119-2 | B29: =COUNTIF($A$2:A29, A29) -> 1 | C29: ML | D29: VM | E29: MN | F29: LX | G29: 5 | H29: 10 | I29: =IF(G29>H29, IF(C29<D29, C29&"/"&D29, D29&"/"&C29), IF(E29<F29, E29&"/"&F29, F29&"/"&E29) ) -> LX/MN | J29: 35m | K29: =_xlfn.CONCAT(A29, "-", B29) -> R20260119-2-1
A30: R20260119-2 | B30: =COUNTIF($A$2:A30, A30) -> 2 | C30: MN | D30: VM | E30: ML | F30: LX | G30: 9 | H30: 10 | I30: =IF(G30>H30, IF(C30<D30, C30&"/"&D30, D30&"/"&C30), IF(E30<F30, E30&"/"&F30, F30&"/"&E30) ) -> LX/ML | J30: 45m | K30: =_xlfn.CONCAT(A30, "-", B30) -> R20260119-2-2
A31: R20260119-2 | B31: =COUNTIF($A$2:A31, A31) -> 3 | C31: VM | D31: LX | E31: ML | F31: MN | G31: 8 | H31: 10 | I31: =IF(G31>H31, IF(C31<D31, C31&"/"&D31, D31&"/"&C31), IF(E31<F31, E31&"/"&F31, F31&"/"&E31) ) -> ML/MN | J31: 70m | K31: =_xlfn.CONCAT(A31, "-", B31) -> R20260119-2-3
A32: R20260127-1 | B32: =COUNTIF($A$2:A32, A32) -> 1 | C32: VM | D32: MN | E32: LX | F32: ML | G32: 2 | H32: 10 | I32: =IF(G32>H32, IF(C32<D32, C32&"/"&D32, D32&"/"&C32), IF(E32<F32, E32&"/"&F32, F32&"/"&E32) ) -> LX/ML | J32: 30m | K32: =_xlfn.CONCAT(A32, "-", B32) -> R20260127-1-1
A33: R20260127-1 | B33: =COUNTIF($A$2:A33, A33) -> 2 | C33: LX | D33: MN | E33: VM | F33: ML | G33: 4 | H33: 10 | I33: =IF(G33>H33, IF(C33<D33, C33&"/"&D33, D33&"/"&C33), IF(E33<F33, E33&"/"&F33, F33&"/"&E33) ) -> ML/VM | J33: 45m | K33: =_xlfn.CONCAT(A33, "-", B33) -> R20260127-1-2
A34: R20260127-1 | B34: =COUNTIF($A$2:A34, A34) -> 3 | C34: LX | D34: VM | E34: ML | F34: MN | G34: 3 | H34: 10 | I34: =IF(G34>H34, IF(C34<D34, C34&"/"&D34, D34&"/"&C34), IF(E34<F34, E34&"/"&F34, F34&"/"&E34) ) -> ML/MN | J34: 45m | K34: =_xlfn.CONCAT(A34, "-", B34) -> R20260127-1-3
A35: R20260127-2 | B35: =COUNTIF($A$2:A35, A35) -> 1 | C35: ML | D35: MN | E35: LX | F35: VM | G35: 9 | H35: 10 | I35: =IF(G35>H35, IF(C35<D35, C35&"/"&D35, D35&"/"&C35), IF(E35<F35, E35&"/"&F35, F35&"/"&E35) ) -> LX/VM | J35: 45m | K35: =_xlfn.CONCAT(A35, "-", B35) -> R20260127-2-1
A36: R20260127-2 | B36: =COUNTIF($A$2:A36, A36) -> 2 | C36: VM | D36: ML | E36: LX | F36: MN | G36: 6 | H36: 10 | I36: =IF(G36>H36, IF(C36<D36, C36&"/"&D36, D36&"/"&C36), IF(E36<F36, E36&"/"&F36, F36&"/"&E36) ) -> LX/MN | J36: 55m | K36: =_xlfn.CONCAT(A36, "-", B36) -> R20260127-2-2
A37: R20260127-2 | B37: =COUNTIF($A$2:A37, A37) -> 3 | C37: ML | D37: LX | E37: VM | F37: MN | G37: 4 | H37: 10 | I37: =IF(G37>H37, IF(C37<D37, C37&"/"&D37, D37&"/"&C37), IF(E37<F37, E37&"/"&F37, F37&"/"&E37) ) -> MN/VM | J37: 40m | K37: =_xlfn.CONCAT(A37, "-", B37) -> R20260127-2-3
... A40: R20260127-3 | B40: =COUNTIF($A$2:A40, A40) -> 3 | C40: ML | D40: MN | E40: LX | F40: VM | G40: 7 | H40: 10 | I40: =IF(G40>H40, IF(C40<D40, C40&"/"&D40, D40&"/"&C40), IF(E40<F40, E40&"/"&F40, F40&"/"&E40) ) -> LX/VM | J40: 50m | K40: =_xlfn.CONCAT(A40, "-", B40) -> R20260127-3-3
A41: R20260203-1 | B41: =COUNTIF($A$2:A41, A41) -> 1 | C41: VM | D41: MN | E41: ML | F41: LX | G41: 8 | H41: 10 | I41: =IF(G41>H41, IF(C41<D41, C41&"/"&D41, D41&"/"&C41), IF(E41<F41, E41&"/"&F41, F41&"/"&E41) ) -> LX/ML | K41: =_xlfn.CONCAT(A41, "-", B41) -> R20260203-1-1
A42: R20260203-1 | B42: =COUNTIF($A$2:A42, A42) -> 2 | C42: ML | D42: MN | E42: LX | F42: VM | G42: 7 | H42: 10 | I42: =IF(G42>H42, IF(C42<D42, C42&"/"&D42, D42&"/"&C42), IF(E42<F42, E42&"/"&F42, F42&"/"&E42) ) -> LX/VM | K42: =_xlfn.CONCAT(A42, "-", B42) -> R20260203-1-2
A43: R20260203-1 | B43: =COUNTIF($A$2:A43, A43) -> 3 | C43: MN | D43: LX | E43: ML | F43: VM | G43: 6 | H43: 10 | I43: =IF(G43>H43, IF(C43<D43, C43&"/"&D43, D43&"/"&C43), IF(E43<F43, E43&"/"&F43, F43&"/"&E43) ) -> ML/VM | K43: =_xlfn.CONCAT(A43, "-", B43) -> R20260203-1-3
A44: R20260203-2 | B44: =COUNTIF($A$2:A44, A44) -> 1 | C44: ML | D44: VM | E44: MN | F44: LX | G44: 7 | H44: 10 | I44: =IF(G44>H44, IF(C44<D44, C44&"/"&D44, D44&"/"&C44), IF(E44<F44, E44&"/"&F44, F44&"/"&E44) ) -> LX/MN | K44: =_xlfn.CONCAT(A44, "-", B44) -> R20260203-2-1
A45: R20260203-2 | B45: =COUNTIF($A$2:A45, A45) -> 2 | C45: LX | D45: ML | E45: MN | F45: VM | G45: 0 | H45: 10 | I45: =IF(G45>H45, IF(C45<D45, C45&"/"&D45, D45&"/"&C45), IF(E45<F45, E45&"/"&F45, F45&"/"&E45) ) -> MN/VM | K45: =_xlfn.CONCAT(A45, "-", B45) -> R20260203-2-2
A46: R20260203-2 | B46: =COUNTIF($A$2:A46, A46) -> 3 | C46: VM | D46: LX | E46: ML | F46: MN | G46: 3 | H46: 10 | I46: =IF(G46>H46, IF(C46<D46, C46&"/"&D46, D46&"/"&C46), IF(E46<F46, E46&"/"&F46, F46&"/"&E46) ) -> ML/MN | K46: =_xlfn.CONCAT(A46, "-", B46) -> R20260203-2-3
A47: R20260203-3 | B47: =COUNTIF($A$2:A47, A47) -> 1 | C47: MN | D47: VM | E47: LX | F47: ML | G47: 7 | H47: 10 | I47: =IF(G47>H47, IF(C47<D47, C47&"/"&D47, D47&"/"&C47), IF(E47<F47, E47&"/"&F47, F47&"/"&E47) ) -> LX/ML | K47: =_xlfn.CONCAT(A47, "-", B47) -> R20260203-3-1
A48: R20260203-3 | B48: =COUNTIF($A$2:A48, A48) -> 2 | C48: ML | D48: MN | E48: LX | F48: VM | G48: 3 | H48: 10 | I48: =IF(G48>H48, IF(C48<D48, C48&"/"&D48, D48&"/"&C48), IF(E48<F48, E48&"/"&F48, F48&"/"&E48) ) -> LX/VM | K48: =_xlfn.CONCAT(A48, "-", B48) -> R20260203-3-2
A49: R20260203-3 | B49: =COUNTIF($A$2:A49, A49) -> 3 | C49: ML | D49: VM | E49: MN | F49: LX | G49: 4 | H49: 10 | I49: =IF(G49>H49, IF(C49<D49, C49&"/"&D49, D49&"/"&C49), IF(E49<F49, E49&"/"&F49, F49&"/"&E49) ) -> LX/MN | K49: =_xlfn.CONCAT(A49, "-", B49) -> R20260203-3-3
A50: R20260216-1 | B50: 1 | C50: ML | D50: VM | E50: MN | F50: LX | G50: 3 | H50: 10 | I50: =IF(G50>H50, IF(C50<D50, C50&"/"&D50, D50&"/"&C50), IF(E50<F50, E50&"/"&F50, F50&"/"&E50) ) -> LX/MN | K50: =_xlfn.CONCAT(A50, "-", B50) -> R20260216-1-1
A51: R20260216-1 | B51: 2 | C51: MN | D51: VM | E51: ML | F51: LX | G51: 3 | H51: 10 | I51: =IF(G51>H51, IF(C51<D51, C51&"/"&D51, D51&"/"&C51), IF(E51<F51, E51&"/"&F51, F51&"/"&E51) ) -> LX/ML | K51: =_xlfn.CONCAT(A51, "-", B51) -> R20260216-1-2
A52: R20260216-1 | B52: 3 | C52: ML | D52: MN | E52: VM | F52: LX | G52: 3 | H52: 10 | I52: =IF(G52>H52, IF(C52<D52, C52&"/"&D52, D52&"/"&C52), IF(E52<F52, E52&"/"&F52, F52&"/"&E52) ) -> LX/VM | K52: =_xlfn.CONCAT(A52, "-", B52) -> R20260216-1-3
A53: R20260216-2 | B53: 1 | C53: MN | D53: LX | E53: ML | F53: VM | G53: 6 | H53: 10 | I53: =IF(G53>H53, IF(C53<D53, C53&"/"&D53, D53&"/"&C53), IF(E53<F53, E53&"/"&F53, F53&"/"&E53) ) -> ML/VM | K53: =_xlfn.CONCAT(A53, "-", B53) -> R20260216-2-1
...

Sheet Betting
A1: SetID | B1: seq | C1: player | D1: bet_tier | E1: outcome | F1: caps | G1: stone_bonus | H1: notes | I1: stones_delta
A2: R20260318-1-1 | B2: 1 | C2: LX | D2: 2/3 | E2: W
A3: R20260318-1-1 | B3: 2 | C3: ML | D3: 2/3 | E3: W
A4: R20260318-1-1 | B4: 3 | C4: ML | D4: 1/2 | E4: W
A5: R20260318-1-1 | B5: 4 | C5: ML | D5: 1/2 | E5: W | F5: Win | G5: 1
A6: R20260318-1-1 | B6: 5 | C6: MN | D6: 2/3 | E6: W
A7: R20260318-1-1 | B7: 6 | C7: MN | D7: 2/3 | E7: W | F7: Win | G7: 1
A8: R20260318-1-1 | B8: 7 | C8: VM | D8: penalty
A9: R20260318-1-1 | B9: 8 | C9: VM | D9: 2/3 | E9: L
A10: R20260318-1-2 | B10: 1 | C10: LX | D10: 1/2 | E10: W
A11: R20260318-1-2 | B11: 2 | C11: ML | D11: 1/2 | E11: L
A12: R20260318-1-2 | B12: 3 | C12: MN | D12: 2/3 | E12: L
A13: R20260318-1-2 | B13: 4 | C13: VM | D13: 2/3 | E13: L
A14: R20260318-1-2 | B14: 5 | C14: VM | D14: 1/2 | E14: W
A15: R20260318-1-2 | B15: 6 | C15: VM | D15: 2/3 | E15: L
A16: R20260318-1-3 | B16: 1 | C16: LX | D16: 1/2 | E16: W
A17: R20260318-1-3 | B17: 2 | C17: LX | D17: 1/2 | E17: W
A18: R20260318-1-3 | B18: 3 | C18: LX | D18: 1/2 | E18: L | F18: Late | H18: V2 late caps on Lewei
A19: R20260318-1-3 | B19: 4 | C19: ML | D19: 3/4 | E19: L
A20: R20260318-1-3 | B20: 5 | C20: ML | D20: 1/2 | E20: L
A21: R20260318-1-3 | B21: 6 | C21: VM | D21: 2/3 | E21: W
A22: R20260318-2-1 | B22: 1 | C22: LX | D22: penalty
A23: R20260318-2-1 | B23: 2 | C23: LX | D23: 2/3 | E23: W
A24: R20260318-2-1 | B24: 3 | C24: LX | D24: 2/3 | E24: W | F24: Win | G24: 1
A25: R20260318-2-1 | B25: 4 | C25: ML | D25: 1/2 | E25: W
A26: R20260318-2-1 | B26: 5 | C26: ML | D26: 1/2 | E26: W
A27: R20260318-2-1 | B27: 6 | C27: ML | D27: 1/2 | E27: W
A28: R20260318-2-1 | B28: 7 | C28: MN | D28: 1/2 | E28: W
A29: R20260318-2-1 | B29: 8 | C29: MN | D29: 1/2 | E29: L
A30: R20260318-2-1 | B30: 9 | C30: MN | D30: 2/3 | E30: L
A31: R20260318-2-1 | B31: 10 | C31: VM | D31: 2/3 | E31: W
A32: R20260318-2-2 | B32: 1 | C32: MN | D32: 2/3 | E32: W | F32: Win | G32: 1
A33: R20260318-2-2 | B33: 2 | C33: MN | D33: 1/2 | E33: L
A34: R20260318-2-2 | B34: 3 | C34: ML | D34: 1/2 | E34: L
A35: R20260318-2-2 | B35: 4 | C35: MN | D35: 2/3 | E35: W
A36: R20260318-2-2 | B36: 5 | C36: LX | D36: 1/2 | E36: L
A37: R20260318-2-2 | B37: 6 | C37: VM | D37: 1/2 | E37: W
A38: R20260318-2-3 | B38: 1 | C38: MN | D38: 2/3 | E38: L
A39: R20260318-2-3 | B39: 2 | C39: ML | D39: 1/2 | E39: W
A40: R20260318-2-3 | B40: 3 | C40: VM | D40: 1/2 | E40: W
...

Sheet By Player
A1: Initial | B1: Name | C1: Revolutions Won | D1: Matches Won | E1: Total Stone Given | F1: Total Score | G1: Last row
A2: LX | B2: Lewei Xu | C2: {=SUMPRODUCT( --( (VALUE(LEFT(INDIRECT("Revolutions!F2:F"&$G$2),FIND(" ",INDIRECT("Revolutions!F2:F"&$G$2))-1)) = _xlfn.BYROW(INDIRECT("Revolutions!F2:I"&$G$2),_xlfn.LAMBDA(_xlpm.r,MAX(VALUE(LEFT(_xlpm.r,FIND(" ",_xlpm.r)-1)))))) * (VALUE(MID(INDIRECT("Revolutions!F2:F"&$G$2),FIND("(",INDIRECT("Revolutions!F2:F"&$G$2))+1, FIND(")",INDIRECT("Revolutions!F2:F"&$G$2))-FIND("(",INDIRECT("Revolutions!F2:F"&$G$2))-1)) = _xlfn.BYROW(INDIRECT("Revolutions!F2:I"&$G$2), _xlfn.LAMBDA(_xlpm.r, _xlfn.LET( _xlpm.m, VALUE(LEFT(_xlpm.r,FIND(" ",_xlpm.r)-1)), _xlpm.s, VALUE(MID(_xlpm.r,FIND("(",_xlpm.r)+1,FIND(")",_xlpm.r)-FIND("(",_xlpm.r)-1)), MAX(IF(_xlpm.m=MAX(_xlpm.m),_xlpm.s)) ) ) ) ) ) )} -> 7 | D2: {=SUMPRODUCT(--LEFT(INDIRECT("Revolutions!F2:F"&$G$2)))} -> 49 | E2: {=SUMPRODUCT(--MID(INDIRECT("Revolutions!F2:F"&$G$2), FIND("(",INDIRECT("Revolutions!F2:F"&$G$2))+1, LEN(INDIRECT("Revolutions!F2:F"&$G$2))-FIND("(",INDIRECT("Revolutions!F2:F"&$G$2))-1))} -> 696 | F2: {=SUM( _xlfn.BYROW(INDIRECT("Revolutions!F2:I"&$G$2), _xlfn.LAMBDA(_xlpm.r, _xlfn.LET( _xlpm.vals,VALUE(LEFT(_xlpm.r,FIND(" ",_xlpm.r)-1))*1000+ VALUE(MID(_xlpm.r,FIND("(",_xlpm.r)+1,FIND(")",_xlpm.r)-FIND("(",_xlpm.r)-1)), _xlpm.me,INDEX(_xlpm.vals,1), _xlpm.rank,1+SUM(--(_xlpm.vals>_xlpm.me)), 5-_xlpm.rank ) ) ) )} -> 79 | G2: {=MATCH(2,1/(Revolutions!A:A<>""),1)} -> 32
